<?xml version="1.0"?>
<sdf version="1.9">
  <model name="mini_talon_vtail">

    <link name="base_link">
      <inertial>
        <pose>0 0 0 0 0 0</pose>
        <mass>5</mass>
        <inertia>
          <ixx>1.0</ixx>
          <ixy>0</ixy>
          <ixz>0</ixz>
          <iyy>1.0</iyy>
          <iyz>0</iyz>
          <izz>1.0</izz>
        </inertia>
      </inertial>

      <collision name="fuselage_collision">
        <pose degrees="true">0 0 0 0 0 0</pose>
        <geometry>
          <mesh>
            <uri>model://mini_talon_vtail/meshes/mini_talon_fuselage_collision.stl</uri>
          </mesh>
        </geometry>
      </collision>

      <collision name="left_wing_collision">
        <pose degrees="true">0 0 0 0 0 0</pose>
        <geometry>
          <mesh>
            <uri>model://mini_talon_vtail/meshes/mini_talon_left_wing_collision.stl</uri>
          </mesh>
        </geometry>
      </collision>

      <collision name="right_wing_collision">
        <pose degrees="true">0 0 0 0 0 0</pose>
        <geometry>
          <mesh>
            <uri>model://mini_talon_vtail/meshes/mini_talon_right_wing_collision.stl</uri>
          </mesh>
        </geometry>
      </collision>

      <collision name="left_tail_collision">
        <pose degrees="true">0 0 0 0 0 0</pose>
        <geometry>
          <mesh>
            <uri>model://mini_talon_vtail/meshes/mini_talon_left_tail_collision.stl</uri>
          </mesh>
        </geometry>
      </collision>

      <collision name="right_tail_collision">
        <pose degrees="true">0 0 0 0 0 0</pose>
        <geometry>
          <mesh>
            <uri>model://mini_talon_vtail/meshes/mini_talon_right_tail_collision.stl</uri>
          </mesh>
        </geometry>
      </collision>

      <visual name="fuselage_visual">
        <pose degrees="true">0 0 0 0 0 0</pose>
        <geometry>
          <mesh>
            <uri>model://mini_talon_vtail/meshes/mini_talon_fuselage.dae</uri>
          </mesh>
        </geometry>
      </visual>

      <visual name="cockpit_frame_visual">
        <pose degrees="true">0 0 0 0 0 0</pose>
        <geometry>
          <mesh>
            <uri>model://mini_talon_vtail/meshes/mini_talon_cockpit_frame.dae</uri>
          </mesh>
        </geometry>
      </visual>

      <visual name="left_wing_visual">
        <pose degrees="true">0 0 0 0 0 0</pose>
        <geometry>
          <mesh>
            <uri>model://mini_talon_vtail/meshes/mini_talon_left_wing.dae</uri>
          </mesh>
        </geometry>
      </visual>

      <visual name="right_wing_visual">
        <pose degrees="true">0 0 0 0 0 0</pose>
        <geometry>
          <mesh>
            <uri>model://mini_talon_vtail/meshes/mini_talon_right_wing.dae</uri>
          </mesh>
        </geometry>
      </visual>

      <visual name="left_tail_visual">
        <pose degrees="true">0 0 0 0 0 0</pose>
        <geometry>
          <mesh>
            <uri>model://mini_talon_vtail/meshes/mini_talon_left_tail.dae</uri>
          </mesh>
        </geometry>
      </visual>

      <visual name="right_tail_visual">
        <pose degrees="true">0 0 0 0 0 0</pose>
        <geometry>
          <mesh>
            <uri>model://mini_talon_vtail/meshes/mini_talon_right_tail.dae</uri>
          </mesh>
        </geometry>
      </visual>

      <visual name="motor_plate_visual">
        <pose degrees="true">-0.41 0 -0.03 0 90 0</pose>
        <geometry>
          <mesh>
            <uri>model://mini_talon_vtail/meshes/propdrive_3536_frontplate.dae</uri>
          </mesh>
        </geometry>
      </visual>

      <visual name="motor_can_visual">
        <pose degrees="true">-0.41 0 -0.03 0 90 0</pose>
        <geometry>
          <mesh>
            <uri>model://mini_talon_vtail/meshes/propdrive_3536_motor_can.dae</uri>
          </mesh>
        </geometry>
      </visual>

      <visual name="propeller_visual">
        <pose degrees="true">-0.415 0 -0.03 0 90 180</pose>
        <geometry>
          <mesh>
            <uri>model://mini_talon_vtail/meshes/iris_prop_cw.dae</uri>
          </mesh>
        </geometry>
        <material>
          <ambient>0.01 0.01 0.01 1</ambient>
          <diffuse>0.01 0.01 0.01 1</diffuse>
          <specular>0.01 0.01 0.01 1</specular>
        </material>
      </visual>


      <!-- Sensors. -->
      <sensor name="imu_sensor" type="imu">
        <pose degrees="true">0 0 0 180 0 0</pose>
        <always_on>1</always_on>
        <update_rate>1000.0</update_rate>
      </sensor>
      <sensor name="navsat_sensor" type="navsat">
        <always_on>1</always_on>
        <update_rate>1</update_rate>
      </sensor>
    </link>

    <link name="main_wheel_link">
      <pose degrees="true">0 0 0 0 0 0</pose>
      <inertial>
        <mass>0.05</mass>
        <inertia>
          <ixx>0.00044</ixx>
          <ixy>0</ixy>
          <ixz>0</ixz>
          <iyy>0.00078</iyy>
          <iyz>0</iyz>
          <izz>0.00044</izz>
        </inertia>
      </inertial>
      <visual name="main_wheel_visual">
        <geometry>
          <mesh>
            <uri>model://mini_talon_vtail/meshes/mini_talon_main_wheel.dae</uri>
          </mesh>
        </geometry>
      </visual>
      <collision name="main_wheel_collision">
        <geometry>
          <mesh>
            <uri>model://mini_talon_vtail/meshes/mini_talon_main_wheel_collision.stl</uri>
          </mesh>
        </geometry>
      </collision>
    </link>
    <joint name="main_wheel_joint" type="revolute">
      <pose degrees="true">0.302018 0 -0.097974 0 0 0</pose>
      <parent>base_link</parent>
      <child>main_wheel_link</child>
      <axis>
        <xyz>0 1 0</xyz>
        <limit>
          <lower>-1.0e-16</lower>
          <upper>1.0e+16</upper>
        </limit>
        <dynamics>
          <damping>0.0001</damping>
        </dynamics>
      </axis>
    </joint>

    <link name="left_aileron_link">
      <pose>0 0 0 0 0 0</pose>
      <inertial>
        <mass>0.010</mass>
        <inertia>
          <ixx>0.06446</ixx>
          <ixy>0</ixy>
          <ixz>0</ixz>
          <iyy>0.000651</iyy>
          <iyz>0</iyz>
          <izz>0.06500</izz>
        </inertia>
      </inertial>
      <visual name="left_aileron_visual">
        <geometry>
          <mesh>
            <uri>model://mini_talon_vtail/meshes/mini_talon_left_aileron.dae</uri>
          </mesh>
        </geometry>
      </visual>
      <visual name="cp_left_aileron_visual">
        <pose degrees="true">-0.093463 0.374976 0.01547 0 0 0</pose>
        <geometry>
          <sphere>
            <radius>0.01</radius>
          </sphere>
        </geometry>
        <material>
          <ambient>1 0 1 1</ambient>
          <diffuse>1 0 1 1</diffuse>
          <specular>0.1 0.1 0.1 1</specular>
        </material>
      </visual>
      <collision name="left_aileron_collision">
        <geometry>
          <mesh>
            <uri>model://mini_talon_vtail/meshes/mini_talon_left_aileron.dae</uri>
          </mesh>
        </geometry>
      </collision>
    </link>
    <joint name="left_aileron_joint" type="revolute">
      <pose relative_to="base_link" degrees="true">-0.093463 0.374976 0.01547 0 0 0</pose>
      <parent>base_link</parent>
      <child>left_aileron_link</child>
      <axis>
        <xyz>0 1 0</xyz>
        <limit>
          <lower>-0.785398</lower>
          <upper>0.785398</upper>
        </limit>
        <dynamics>
          <damping>0.0001</damping>
        </dynamics>
      </axis>
    </joint>

    <link name="right_aileron_link">
      <pose>0 0 0 0 0 0</pose>
      <inertial>
        <mass>0.010</mass>
        <inertia>
          <ixx>0.06446</ixx>
          <ixy>0</ixy>
          <ixz>0</ixz>
          <iyy>0.000651</iyy>
          <iyz>0</iyz>
          <izz>0.06500</izz>
        </inertia>
      </inertial>
      <visual name="right_aileron_visual">
        <geometry>
          <mesh>
            <uri>model://mini_talon_vtail/meshes/mini_talon_right_aileron.dae</uri>
          </mesh>
        </geometry>
      </visual>
      <visual name="cp_right_aileron_visual">
        <pose degrees="true">-0.093463 -0.374976 0.01547 0 0 0</pose>
        <geometry>
          <sphere>
            <radius>0.01</radius>
          </sphere>
        </geometry>
        <material>
          <ambient>1 0 1 1</ambient>
          <diffuse>1 0 1 1</diffuse>
          <specular>0.1 0.1 0.1 1</specular>
        </material>
      </visual>
      <collision name="right_aileron_collision">
        <geometry>
          <mesh>
            <uri>model://mini_talon_vtail/meshes/mini_talon_right_aileron.dae</uri>
          </mesh>
        </geometry>
      </collision>
    </link>
    <joint name="right_aileron_joint" type="revolute">
      <pose relative_to="base_link" degrees="true">-0.093463 -0.374976 0.01547 0 0 0</pose>
      <parent>base_link</parent>
      <child>right_aileron_link</child>
      <axis>
        <xyz>0 1 0</xyz>
        <limit>
          <lower>-0.785398</lower>
          <upper>0.785398</upper>
        </limit>
        <dynamics>
          <damping>0.0001</damping>
        </dynamics>
      </axis>
    </joint>

    <link name="left_rudder_link">
      <pose>0 0 0 0 0 0</pose>
      <inertial>
        <mass>0.010</mass>
        <inertia>
          <ixx>0.06446</ixx>
          <ixy>0</ixy>
          <ixz>0</ixz>
          <iyy>0.000651</iyy>
          <iyz>0</iyz>
          <izz>0.06500</izz>
        </inertia>
      </inertial>
      <visual name="left_rudder_visual">
        <geometry>
          <mesh>
            <uri>model://mini_talon_vtail/meshes/mini_talon_left_rudder.dae</uri>
          </mesh>
        </geometry>
      </visual>
      <visual name="cp_left_rudder_visual">
        <pose degrees="true">-0.356979 0.073648 0.040507 0 0 0</pose>
        <geometry>
          <sphere>
            <radius>0.01</radius>
          </sphere>
        </geometry>
        <material>
          <ambient>1 0 1 1</ambient>
          <diffuse>1 0 1 1</diffuse>
          <specular>0.1 0.1 0.1 1</specular>
        </material>
      </visual>
      <collision name="left_rudder_collision">
        <geometry>
          <mesh>
            <uri>model://mini_talon_vtail/meshes/mini_talon_left_rudder.dae</uri>
          </mesh>
        </geometry>
      </collision>
    </link>
    <joint name="left_rudder_joint" type="revolute">
      <pose relative_to="base_link" degrees="true">-0.356979 0.073648 0.040507 45 -15 0</pose>
      <parent>base_link</parent>
      <child>left_rudder_link</child>
      <axis>
        <xyz>0 1 0</xyz>
        <limit>
          <lower>-0.785398</lower>
          <upper>0.785398</upper>
        </limit>
        <dynamics>
          <damping>0.0001</damping>
        </dynamics>
      </axis>
    </joint>

    <link name="right_rudder_link">
      <pose>0 0 0 0 0 0</pose>
      <inertial>
        <mass>0.010</mass>
        <inertia>
          <ixx>0.06446</ixx>
          <ixy>0</ixy>
          <ixz>0</ixz>
          <iyy>0.000651</iyy>
          <iyz>0</iyz>
          <izz>0.06500</izz>
        </inertia>
      </inertial>
      <visual name="right_rudder_visual">
        <geometry>
          <mesh>
            <uri>model://mini_talon_vtail/meshes/mini_talon_right_rudder.dae</uri>
          </mesh>
        </geometry>
      </visual>
      <visual name="cp_right_rudder_visual">
        <pose degrees="true">-0.356979 -0.073648 0.040507 0 0 0</pose>
        <geometry>
          <sphere>
            <radius>0.01</radius>
          </sphere>
        </geometry>
        <material>
          <ambient>1 0 1 1</ambient>
          <diffuse>1 0 1 1</diffuse>
          <specular>0.1 0.1 0.1 1</specular>
        </material>
      </visual>
      <collision name="right_rudder_collision">
        <geometry>
          <mesh>
            <uri>model://mini_talon_vtail/meshes/mini_talon_right_rudder.dae</uri>
          </mesh>
        </geometry>
      </collision>
    </link>
    <joint name="right_rudder_joint" type="revolute">
      <pose relative_to="base_link" degrees="true">-0.356979 -0.073648 0.040507 -45 -15 0</pose>
      <parent>base_link</parent>
      <child>right_rudder_link</child>
      <axis>
        <xyz>0 1 0</xyz>
        <limit>
          <lower>-0.785398</lower>
          <upper>0.785398</upper>
        </limit>
        <dynamics>
          <damping>0.0001</damping>
        </dynamics>
      </axis>
    </joint>

    <!-- System plugins. -->
    <plugin filename="gz-sim-joint-state-publisher-system"
      name="gz::sim::systems::JointStatePublisher">
    </plugin>

    <!-- Positive is up. -->
    <plugin
      filename="gz-sim-joint-position-controller-system"
      name="gz::sim::systems::JointPositionController">
      <joint_name>left_aileron_joint</joint_name>
      <initial_position>0.0</initial_position>
      <topic>/left_aileron_joint/cmd_pos</topic>
      <p_gain>5</p_gain>
      <i_gain>0.5</i_gain>
      <d_gain>0.5</d_gain>
      <i_max>5</i_max>
      <i_min>-5</i_min>
      <cmd_max>200</cmd_max>
      <cmd_min>-200</cmd_min>
    </plugin>

    <!-- Positive is up. -->
    <plugin
      filename="gz-sim-joint-position-controller-system"
      name="gz::sim::systems::JointPositionController">
      <joint_name>right_aileron_joint</joint_name>
      <initial_position>0.0</initial_position>
      <topic>/right_aileron_joint/cmd_pos</topic>
      <p_gain>5</p_gain>
      <i_gain>0.5</i_gain>
      <d_gain>0.5</d_gain>
      <i_max>5</i_max>
      <i_min>-5</i_min>
      <cmd_max>200</cmd_max>
      <cmd_min>-200</cmd_min>
    </plugin>

    <!-- Positive is up. -->
    <plugin
      filename="gz-sim-joint-position-controller-system"
      name="gz::sim::systems::JointPositionController">
      <joint_name>left_rudder_joint</joint_name>
      <initial_position>0.0</initial_position>
      <topic>/left_rudder_joint/cmd_pos</topic>
      <p_gain>5</p_gain>
      <i_gain>0.5</i_gain>
      <d_gain>0.5</d_gain>
      <i_max>5</i_max>
      <i_min>-5</i_min>
      <cmd_max>200</cmd_max>
      <cmd_min>-200</cmd_min>
    </plugin>

    <!-- Positive is up. -->
    <plugin
      filename="gz-sim-joint-position-controller-system"
      name="gz::sim::systems::JointPositionController">
      <joint_name>right_rudder_joint</joint_name>
      <initial_position>0.0</initial_position>
      <topic>/right_rudder_joint/cmd_pos</topic>
      <p_gain>5</p_gain>
      <i_gain>0.5</i_gain>
      <d_gain>0.5</d_gain>
      <i_max>5</i_max>
      <i_min>-5</i_min>
      <cmd_max>200</cmd_max>
      <cmd_min>-200</cmd_min>
    </plugin>

  </model>
</sdf>

