<?xml version="1.0"?>
<sdf version="1.9">
  <model name="titan_cobra_vtol">
    <pose>0 0 0 0 0 0</pose>
    <static>0</static>

    <link name="base_link">`
      <inertial>
        <pose>-0.054 0 0 0 0 0</pose>
        <mass>3.5</mass>
        <inertia>
          <ixx>0.010645833</ixx>
          <ixy>0</ixy>
          <ixz>0</ixz>
          <iyy>0.109929167</iyy>
          <iyz>0</iyz>
          <izz>0.110716667</izz>
        </inertia>
      </inertial>

      <collision name="collision">
        <geometry>
          <mesh>
            <uri>model://titan_cobra_vtol/meshes/titan_cobra_vtol.dae</uri>
            <submesh>
              <name>~CS_FUSELAGE</name>
            </submesh>
          </mesh>
        </geometry>
      </collision>

      <visual name="fuselage_visual">
        <geometry>
          <mesh>
            <uri>model://titan_cobra_vtol/meshes/titan_cobra_vtol.dae</uri>
            <submesh>
              <name>~CS_FUSELAGE</name>
            </submesh>
          </mesh>
        </geometry>
        <material>
          <ambient>1 1 1</ambient>
          <diffuse>1 1 1</diffuse>
          <specular>0.5 0.5 0.5</specular>
          <pbr>
            <metal>
              <albedo_map>model://titan_cobra_vtol/meshes/TitanCobraTexture.tga</albedo_map>
              <roughness>0.5</roughness>
              <metalness>0.5</metalness> 
            </metal>
          </pbr>
        </material>
      </visual>

      <visual name="airspeed_visual">
        <geometry>
          <mesh>
            <uri>model://titan_cobra_vtol/meshes/titan_cobra_vtol.dae</uri>
            <submesh>
              <name>~CS_Airspeed</name>
            </submesh>
          </mesh>
        </geometry>
        <material>
          <ambient>1 1 1</ambient>
          <diffuse>1 1 1</diffuse>
          <specular>0.5 0.5 0.5</specular>
          <pbr>
            <metal>
              <albedo_map>model://titan_cobra_vtol/meshes/TitanCobraTexture.tga</albedo_map>
              <roughness>0.5</roughness>
              <metalness>0.5</metalness> 
            </metal>
          </pbr>
        </material>
      </visual>

      <visual name="fpv_cam_visual">
        <geometry>
          <mesh>
            <uri>model://titan_cobra_vtol/meshes/titan_cobra_vtol.dae</uri>
            <submesh>
              <name>FPVCAM</name>
            </submesh>
          </mesh>
        </geometry>
        <material>
          <ambient>1 1 1</ambient>
          <diffuse>1 1 1</diffuse>
          <specular>0.5 0.5 0.5</specular>
          <pbr>
            <metal>
              <albedo_map>model://titan_cobra_vtol/meshes/TitanCobraTexture.tga</albedo_map>
              <roughness>0.5</roughness>
              <metalness>0.5</metalness> 
            </metal>
          </pbr>
        </material>
      </visual>

      <visual name="pusher_mount_visual">
        <geometry>
          <mesh>
            <uri>model://titan_cobra_vtol/meshes/titan_cobra_vtol.dae</uri>
            <submesh>
              <name>~CS_PusherMount</name>
            </submesh>
          </mesh>
        </geometry>
        <material>
          <ambient>1 1 1</ambient>
          <diffuse>1 1 1</diffuse>
          <specular>0.5 0.5 0.5</specular>
          <pbr>
            <metal>
              <albedo_map>model://titan_cobra_vtol/meshes/TitanCobraTexture.tga</albedo_map>
              <roughness>0.5</roughness>
              <metalness>0.5</metalness> 
            </metal>
          </pbr>
        </material>
      </visual>

      <visual name="stator_5_visual">
        <geometry>
          <mesh>
            <uri>model://titan_cobra_vtol/meshes/titan_cobra_vtol.dae</uri>
            <submesh>
              <name>~CS_STATOR5</name>
            </submesh>
          </mesh>
        </geometry>
        <material>
          <ambient>1 1 1</ambient>
          <diffuse>1 1 1</diffuse>
          <specular>0.5 0.5 0.5</specular>
          <pbr>
            <metal>
              <albedo_map>model://titan_cobra_vtol/meshes/TitanCobraTexture.tga</albedo_map>
              <roughness>0.5</roughness>
              <metalness>0.5</metalness> 
            </metal>
          </pbr>
        </material>
      </visual>

      <!-- <visual name="spinner_5_visual">
        <geometry>
          <mesh>
            <uri>model://titan_cobra_vtol/meshes/titan_cobra_vtol.dae</uri>
            <submesh>
              <name>~CS_SPINNER5</name>
            </submesh>
          </mesh>
        </geometry>
        <material>
          <ambient>1 1 1</ambient>
          <diffuse>1 1 1</diffuse>
          <specular>0.5 0.5 0.5</specular>
          <pbr>
            <metal>
              <albedo_map>model://titan_cobra_vtol/meshes/TitanCobraTexture.tga</albedo_map>
              <roughness>0.5</roughness>
              <metalness>0.5</metalness> 
            </metal>
          </pbr>
        </material>
      </visual>

      <visual name="engine_5_visual">
        <geometry>
          <mesh>
            <uri>model://titan_cobra_vtol/meshes/titan_cobra_vtol.dae</uri>
            <submesh>
              <name>~CS_ENGINE5</name>
            </submesh>
          </mesh>
        </geometry>
        <material>
          <ambient>1 1 1</ambient>
          <diffuse>1 1 1</diffuse>
          <specular>0.5 0.5 0.5</specular>
          <pbr>
            <metal>
              <albedo_map>model://titan_cobra_vtol/meshes/TitanCobraTexture.tga</albedo_map>
              <roughness>0.5</roughness>
              <metalness>0.5</metalness> 
            </metal>
          </pbr>
        </material>
      </visual> -->

      <visual name="left_main_wing_visual">
        <geometry>
          <mesh>
            <uri>model://titan_cobra_vtol/meshes/titan_cobra_vtol.dae</uri>
            <submesh>
              <name>~CS_LMW</name>
            </submesh>
          </mesh>
        </geometry>
        <material>
          <ambient>1 1 1</ambient>
          <diffuse>1 1 1</diffuse>
          <specular>0.5 0.5 0.5</specular>
          <pbr>
            <metal>
              <albedo_map>model://titan_cobra_vtol/meshes/TitanCobraTexture.tga</albedo_map>
              <roughness>0.5</roughness>
              <metalness>0.5</metalness> 
            </metal>
          </pbr>
        </material>
      </visual>

      <!-- <visual name="left_aileron_visual">
        <geometry>
          <mesh>
            <uri>model://titan_cobra_vtol/meshes/titan_cobra_vtol.dae</uri>
            <submesh>
              <name>~CS_LA</name>
            </submesh>
          </mesh>
        </geometry>
        <material>
          <ambient>1 1 1</ambient>
          <diffuse>1 1 1</diffuse>
          <specular>0.5 0.5 0.5</specular>
          <pbr>
            <metal>
              <albedo_map>model://titan_cobra_vtol/meshes/TitanCobraTexture.tga</albedo_map>
              <roughness>0.5</roughness>
              <metalness>0.5</metalness> 
            </metal>
          </pbr>
        </material>
      </visual> -->

      <visual name="left_boom_mount_visual">
        <geometry>
          <mesh>
            <uri>model://titan_cobra_vtol/meshes/titan_cobra_vtol.dae</uri>
            <submesh>
              <name>LBoomMount</name>
            </submesh>
          </mesh>
        </geometry>
        <material>
          <ambient>1 1 1</ambient>
          <diffuse>1 1 1</diffuse>
          <specular>0.5 0.5 0.5</specular>
          <pbr>
            <metal>
              <albedo_map>model://titan_cobra_vtol/meshes/TitanCobraTexture.tga</albedo_map>
              <roughness>0.5</roughness>
              <metalness>0.5</metalness> 
            </metal>
          </pbr>
        </material>
      </visual>

      <visual name="left_boom_visual">
        <geometry>
          <mesh>
            <uri>model://titan_cobra_vtol/meshes/titan_cobra_vtol.dae</uri>
            <submesh>
              <name>~CS_LBoom</name>
            </submesh>
          </mesh>
        </geometry>
        <material>
          <ambient>1 1 1</ambient>
          <diffuse>1 1 1</diffuse>
          <specular>0.5 0.5 0.5</specular>
          <pbr>
            <metal>
              <albedo_map>model://titan_cobra_vtol/meshes/TitanCobraTexture.tga</albedo_map>
              <roughness>0.5</roughness>
              <metalness>0.5</metalness> 
            </metal>
          </pbr>
        </material>
      </visual>

      <visual name="left_tail_visual">
        <geometry>
          <mesh>
            <uri>model://titan_cobra_vtol/meshes/titan_cobra_vtol.dae</uri>
            <submesh>
              <name>~CS_LTail</name>
            </submesh>
          </mesh>
        </geometry>
        <material>
          <ambient>1 1 1</ambient>
          <diffuse>1 1 1</diffuse>
          <specular>0.5 0.5 0.5</specular>
          <pbr>
            <metal>
              <albedo_map>model://titan_cobra_vtol/meshes/TitanCobraTexture.tga</albedo_map>
              <roughness>0.5</roughness>
              <metalness>0.5</metalness> 
            </metal>
          </pbr>
        </material>
      </visual>

      <!-- <visual name="left_ruddervator_visual">
        <geometry>
          <mesh>
            <uri>model://titan_cobra_vtol/meshes/titan_cobra_vtol.dae</uri>
            <submesh>
              <name>~CS_LRV</name>
            </submesh>
          </mesh>
        </geometry>
        <material>
          <ambient>1 1 1</ambient>
          <diffuse>1 1 1</diffuse>
          <specular>0.5 0.5 0.5</specular>
          <pbr>
            <metal>
              <albedo_map>model://titan_cobra_vtol/meshes/TitanCobraTexture.tga</albedo_map>
              <roughness>0.5</roughness>
              <metalness>0.5</metalness> 
            </metal>
          </pbr>
        </material>
      </visual> -->

      <visual name="motor_mount_2_visual">
        <pose degrees="true">-0.335 0 0.412 0 -90 0</pose>
        <geometry>
          <mesh>
            <uri>model://titan_cobra_vtol/meshes/titan_cobra_vtol.dae</uri>
            <submesh>
              <name>~CS_MotorMount2</name>
            </submesh>
          </mesh>
        </geometry>
        <material>
          <ambient>1 1 1</ambient>
          <diffuse>1 1 1</diffuse>
          <specular>0.5 0.5 0.5</specular>
          <pbr>
            <metal>
              <albedo_map>model://titan_cobra_vtol/meshes/TitanCobraTexture.tga</albedo_map>
              <roughness>0.5</roughness>
              <metalness>0.5</metalness> 
            </metal>
          </pbr>
        </material>
      </visual>

      <visual name="stator_2_visual">
        <pose degrees="true">-0.335 0 0.412 0 -90 0</pose>
        <geometry>
          <mesh>
            <uri>model://titan_cobra_vtol/meshes/titan_cobra_vtol.dae</uri>
            <submesh>
              <name>~CS_STATOR2</name>
            </submesh>
          </mesh>
        </geometry>
        <material>
          <ambient>1 1 1</ambient>
          <diffuse>1 1 1</diffuse>
          <specular>0.5 0.5 0.5</specular>
          <pbr>
            <metal>
              <albedo_map>model://titan_cobra_vtol/meshes/TitanCobraTexture.tga</albedo_map>
              <roughness>0.5</roughness>
              <metalness>0.5</metalness> 
            </metal>
          </pbr>
        </material>
      </visual>

      <!-- <visual name="spinner_2_visual">
        <pose degrees="true">-0.335 0 0.412 0 -90 0</pose>
        <geometry>
          <mesh>
            <uri>model://titan_cobra_vtol/meshes/titan_cobra_vtol.dae</uri>
            <submesh>
              <name>~CS_SPINNER2</name>
            </submesh>
          </mesh>
        </geometry>
        <material>
          <ambient>1 1 1</ambient>
          <diffuse>1 1 1</diffuse>
          <specular>0.5 0.5 0.5</specular>
          <pbr>
            <metal>
              <albedo_map>model://titan_cobra_vtol/meshes/TitanCobraTexture.tga</albedo_map>
              <roughness>0.5</roughness>
              <metalness>0.5</metalness> 
            </metal>
          </pbr>
        </material>
      </visual>

      <visual name="engine_2_visual">
        <pose degrees="true">-0.335 0 0.412 0 -90 0</pose>
        <geometry>
          <mesh>
            <uri>model://titan_cobra_vtol/meshes/titan_cobra_vtol.dae</uri>
            <submesh>
              <name>~CS_ENGINE2</name>
            </submesh>
          </mesh>
        </geometry>
        <material>
          <ambient>1 1 1</ambient>
          <diffuse>1 1 1</diffuse>
          <specular>0.5 0.5 0.5</specular>
          <pbr>
            <metal>
              <albedo_map>model://titan_cobra_vtol/meshes/TitanCobraTexture.tga</albedo_map>
              <roughness>0.5</roughness>
              <metalness>0.5</metalness> 
            </metal>
          </pbr>
        </material>
      </visual> -->

      <visual name="motor_mount_3_visual">
        <pose degrees="true">0.22 0 -0.147 0 -90 0</pose>
        <geometry>
          <mesh>
            <uri>model://titan_cobra_vtol/meshes/titan_cobra_vtol.dae</uri>
            <submesh>
              <name>~CS_MotorMount3</name>
            </submesh>
          </mesh>
        </geometry>
        <material>
          <ambient>1 1 1</ambient>
          <diffuse>1 1 1</diffuse>
          <specular>0.5 0.5 0.5</specular>
          <pbr>
            <metal>
              <albedo_map>model://titan_cobra_vtol/meshes/TitanCobraTexture.tga</albedo_map>
              <roughness>0.5</roughness>
              <metalness>0.5</metalness> 
            </metal>
          </pbr>
        </material>
      </visual>

      <visual name="stator_3_visual">
        <pose degrees="true">0.22 0 -0.147 0 -90 0</pose>
        <geometry>
          <mesh>
            <uri>model://titan_cobra_vtol/meshes/titan_cobra_vtol.dae</uri>
            <submesh>
              <name>~CS_STATOR3</name>
            </submesh>
          </mesh>
        </geometry>
        <material>
          <ambient>1 1 1</ambient>
          <diffuse>1 1 1</diffuse>
          <specular>0.5 0.5 0.5</specular>
          <pbr>
            <metal>
              <albedo_map>model://titan_cobra_vtol/meshes/TitanCobraTexture.tga</albedo_map>
              <roughness>0.5</roughness>
              <metalness>0.5</metalness> 
            </metal>
          </pbr>
        </material>
      </visual>

      <!-- <visual name="spinner_3_visual">
        <pose degrees="true">0.22 0 -0.147 0 -90 0</pose>
        <geometry>
          <mesh>
            <uri>model://titan_cobra_vtol/meshes/titan_cobra_vtol.dae</uri>
            <submesh>
              <name>~CS_SPINNER3</name>
            </submesh>
          </mesh>
        </geometry>
        <material>
          <ambient>1 1 1</ambient>
          <diffuse>1 1 1</diffuse>
          <specular>0.5 0.5 0.5</specular>
          <pbr>
            <metal>
              <albedo_map>model://titan_cobra_vtol/meshes/TitanCobraTexture.tga</albedo_map>
              <roughness>0.5</roughness>
              <metalness>0.5</metalness> 
            </metal>
          </pbr>
        </material>
      </visual>

      <visual name="engine_3_visual">
        <pose degrees="true">0.22 0 -0.147 0 -90 0</pose>
        <geometry>
          <mesh>
            <uri>model://titan_cobra_vtol/meshes/titan_cobra_vtol.dae</uri>
            <submesh>
              <name>~CS_ENGINE3</name>
            </submesh>
          </mesh>
        </geometry>
        <material>
          <ambient>1 1 1</ambient>
          <diffuse>1 1 1</diffuse>
          <specular>0.5 0.5 0.5</specular>
          <pbr>
            <metal>
              <albedo_map>model://titan_cobra_vtol/meshes/TitanCobraTexture.tga</albedo_map>
              <roughness>0.5</roughness>
              <metalness>0.5</metalness> 
            </metal>
          </pbr>
        </material>
      </visual> -->

      <visual name="right_main_wing_visual">
        <geometry>
          <mesh>
            <uri>model://titan_cobra_vtol/meshes/titan_cobra_vtol.dae</uri>
            <submesh>
              <name>~CS_RMW</name>
            </submesh>
          </mesh>
        </geometry>
        <material>
          <ambient>1 1 1</ambient>
          <diffuse>1 1 1</diffuse>
          <specular>0.5 0.5 0.5</specular>
          <pbr>
            <metal>
              <albedo_map>model://titan_cobra_vtol/meshes/TitanCobraTexture.tga</albedo_map>
              <roughness>0.5</roughness>
              <metalness>0.5</metalness> 
            </metal>
          </pbr>
        </material>
      </visual>

      <!-- <visual name="right_aileron_visual">
        <geometry>
          <mesh>
            <uri>model://titan_cobra_vtol/meshes/titan_cobra_vtol.dae</uri>
            <submesh>
              <name>~CS_RA</name>
            </submesh>
          </mesh>
        </geometry>
        <material>
          <ambient>1 1 1</ambient>
          <diffuse>1 1 1</diffuse>
          <specular>0.5 0.5 0.5</specular>
          <pbr>
            <metal>
              <albedo_map>model://titan_cobra_vtol/meshes/TitanCobraTexture.tga</albedo_map>
              <roughness>0.5</roughness>
              <metalness>0.5</metalness> 
            </metal>
          </pbr>
        </material>
      </visual> -->

      <visual name="right_boom_mount_visual">
        <geometry>
          <mesh>
            <uri>model://titan_cobra_vtol/meshes/titan_cobra_vtol.dae</uri>
            <submesh>
              <name>RBoomMount</name>
            </submesh>
          </mesh>
        </geometry>
        <material>
          <ambient>1 1 1</ambient>
          <diffuse>1 1 1</diffuse>
          <specular>0.5 0.5 0.5</specular>
          <pbr>
            <metal>
              <albedo_map>model://titan_cobra_vtol/meshes/TitanCobraTexture.tga</albedo_map>
              <roughness>0.5</roughness>
              <metalness>0.5</metalness> 
            </metal>
          </pbr>
        </material>
      </visual>

      <visual name="right_boom_visual">
        <geometry>
          <mesh>
            <uri>model://titan_cobra_vtol/meshes/titan_cobra_vtol.dae</uri>
            <submesh>
              <name>~CS_RBoom</name>
            </submesh>
          </mesh>
        </geometry>
        <material>
          <ambient>1 1 1</ambient>
          <diffuse>1 1 1</diffuse>
          <specular>0.5 0.5 0.5</specular>
          <pbr>
            <metal>
              <albedo_map>model://titan_cobra_vtol/meshes/TitanCobraTexture.tga</albedo_map>
              <roughness>0.5</roughness>
              <metalness>0.5</metalness> 
            </metal>
          </pbr>
        </material>
      </visual>

      <visual name="right_tail_visual">
        <geometry>
          <mesh>
            <uri>model://titan_cobra_vtol/meshes/titan_cobra_vtol.dae</uri>
            <submesh>
              <name>~CS_RTail</name>
            </submesh>
          </mesh>
        </geometry>
        <material>
          <ambient>1 1 1</ambient>
          <diffuse>1 1 1</diffuse>
          <specular>0.5 0.5 0.5</specular>
          <pbr>
            <metal>
              <albedo_map>model://titan_cobra_vtol/meshes/TitanCobraTexture.tga</albedo_map>
              <roughness>0.5</roughness>
              <metalness>0.5</metalness> 
            </metal>
          </pbr>
        </material>
      </visual>

      <!-- <visual name="right_ruddervator_visual">
        <geometry>
          <mesh>
            <uri>model://titan_cobra_vtol/meshes/titan_cobra_vtol.dae</uri>
            <submesh>
              <name>~CS_RRV</name>
            </submesh>
          </mesh>
        </geometry>
        <material>
          <ambient>1 1 1</ambient>
          <diffuse>1 1 1</diffuse>
          <specular>0.5 0.5 0.5</specular>
          <pbr>
            <metal>
              <albedo_map>model://titan_cobra_vtol/meshes/TitanCobraTexture.tga</albedo_map>
              <roughness>0.5</roughness>
              <metalness>0.5</metalness> 
            </metal>
          </pbr>
        </material>
      </visual> -->

      <visual name="motor_mount_1_visual">
        <pose degrees="true">0.22 0 -0.147 0 -90 0</pose>
        <geometry>
          <mesh>
            <uri>model://titan_cobra_vtol/meshes/titan_cobra_vtol.dae</uri>
            <submesh>
              <name>~CS_MotorMount1</name>
            </submesh>
          </mesh>
        </geometry>
        <material>
          <ambient>1 1 1</ambient>
          <diffuse>1 1 1</diffuse>
          <specular>0.5 0.5 0.5</specular>
          <pbr>
            <metal>
              <albedo_map>model://titan_cobra_vtol/meshes/TitanCobraTexture.tga</albedo_map>
              <roughness>0.5</roughness>
              <metalness>0.5</metalness> 
            </metal>
          </pbr>
        </material>
      </visual>

      <visual name="stator_1_visual">
        <pose degrees="true">0.22 0 -0.147 0 -90 0</pose>
        <geometry>
          <mesh>
            <uri>model://titan_cobra_vtol/meshes/titan_cobra_vtol.dae</uri>
            <submesh>
              <name>~CS_STATOR1</name>
            </submesh>
          </mesh>
        </geometry>
        <material>
          <ambient>1 1 1</ambient>
          <diffuse>1 1 1</diffuse>
          <specular>0.5 0.5 0.5</specular>
          <pbr>
            <metal>
              <albedo_map>model://titan_cobra_vtol/meshes/TitanCobraTexture.tga</albedo_map>
              <roughness>0.5</roughness>
              <metalness>0.5</metalness> 
            </metal>
          </pbr>
        </material>
      </visual>

      <!-- <visual name="spinner_1_visual">
        <pose degrees="true">0.22 0 -0.147 0 -90 0</pose>
        <geometry>
          <mesh>
            <uri>model://titan_cobra_vtol/meshes/titan_cobra_vtol.dae</uri>
            <submesh>
              <name>~CS_SPINNER1</name>
            </submesh>
          </mesh>
        </geometry>
        <material>
          <ambient>1 1 1</ambient>
          <diffuse>1 1 1</diffuse>
          <specular>0.5 0.5 0.5</specular>
          <pbr>
            <metal>
              <albedo_map>model://titan_cobra_vtol/meshes/TitanCobraTexture.tga</albedo_map>
              <roughness>0.5</roughness>
              <metalness>0.5</metalness> 
            </metal>
          </pbr>
        </material>
      </visual>

      <visual name="engine_1_visual">
        <pose degrees="true">0.22 0 -0.147 0 -90 0</pose>
        <geometry>
          <mesh>
            <uri>model://titan_cobra_vtol/meshes/titan_cobra_vtol.dae</uri>
            <submesh>
              <name>~CS_ENGINE1</name>
            </submesh>
          </mesh>
        </geometry>
        <material>
          <ambient>1 1 1</ambient>
          <diffuse>1 1 1</diffuse>
          <specular>0.5 0.5 0.5</specular>
          <pbr>
            <metal>
              <albedo_map>model://titan_cobra_vtol/meshes/TitanCobraTexture.tga</albedo_map>
              <roughness>0.5</roughness>
              <metalness>0.5</metalness> 
            </metal>
          </pbr>
        </material>
      </visual> -->

      <visual name="motor_mount_4_visual">
        <pose degrees="true">-0.335 0 0.412 0 -90 0</pose>
        <geometry>
          <mesh>
            <uri>model://titan_cobra_vtol/meshes/titan_cobra_vtol.dae</uri>
            <submesh>
              <name>~CS_MotorMount4</name>
            </submesh>
          </mesh>
        </geometry>
        <material>
          <ambient>1 1 1</ambient>
          <diffuse>1 1 1</diffuse>
          <specular>0.5 0.5 0.5</specular>
          <pbr>
            <metal>
              <albedo_map>model://titan_cobra_vtol/meshes/TitanCobraTexture.tga</albedo_map>
              <roughness>0.5</roughness>
              <metalness>0.5</metalness> 
            </metal>
          </pbr>
        </material>
      </visual>

      <visual name="stator_4_visual">
        <pose degrees="true">-0.335 0 0.412 0 -90 0</pose>
        <geometry>
          <mesh>
            <uri>model://titan_cobra_vtol/meshes/titan_cobra_vtol.dae</uri>
            <submesh>
              <name>~CS_STATOR4</name>
            </submesh>
          </mesh>
        </geometry>
        <material>
          <ambient>1 1 1</ambient>
          <diffuse>1 1 1</diffuse>
          <specular>0.5 0.5 0.5</specular>
          <pbr>
            <metal>
              <albedo_map>model://titan_cobra_vtol/meshes/TitanCobraTexture.tga</albedo_map>
              <roughness>0.5</roughness>
              <metalness>0.5</metalness> 
            </metal>
          </pbr>
        </material>
      </visual>

      <!-- <visual name="spinner_4_visual">
        <pose degrees="true">-0.335 0 0.412 0 -90 0</pose>
        <geometry>
          <mesh>
            <uri>model://titan_cobra_vtol/meshes/titan_cobra_vtol.dae</uri>
            <submesh>
              <name>~CS_SPINNER4</name>
            </submesh>
          </mesh>
        </geometry>
        <material>
          <ambient>1 1 1</ambient>
          <diffuse>1 1 1</diffuse>
          <specular>0.5 0.5 0.5</specular>
          <pbr>
            <metal>
              <albedo_map>model://titan_cobra_vtol/meshes/TitanCobraTexture.tga</albedo_map>
              <roughness>0.5</roughness>
              <metalness>0.5</metalness> 
            </metal>
          </pbr>
        </material>
      </visual>

      <visual name="engine_4_visual">
        <pose degrees="true">-0.335 0 0.412 0 -90 0</pose>
        <geometry>
          <mesh>
            <uri>model://titan_cobra_vtol/meshes/titan_cobra_vtol.dae</uri>
            <submesh>
              <name>~CS_ENGINE4</name>
            </submesh>
          </mesh>
        </geometry>
        <material>
          <ambient>1 1 1</ambient>
          <diffuse>1 1 1</diffuse>
          <specular>0.5 0.5 0.5</specular>
          <pbr>
            <metal>
              <albedo_map>model://titan_cobra_vtol/meshes/TitanCobraTexture.tga</albedo_map>
              <roughness>0.5</roughness>
              <metalness>0.5</metalness> 
            </metal>
          </pbr>
        </material>
      </visual> -->
    </link>

    <!-- control surfaces -->
    <link name="left_aileron_link">
      <pose relative_to="base_link" degrees="true">-0.115848 0.66957 0.056213 0 0 0</pose>
      <inertial>
        <pose degrees="true">-0.035 0 0 0 0 0</pose>
        <mass>0.1</mass>
        <inertia>
          <ixx>0.000477985</ixx>
          <ixy>0</ixy>
          <iyy>4.66283E-05</iyy>
          <ixz>0</ixz>
          <iyz>0</iyz>
          <izz>0.00052066</izz>
        </inertia>
      </inertial>
      <collision name="aileron_collision">
        <pose degrees="true">-0.035 0 0 0 0 0</pose>
        <geometry>
          <box>
            <size>0.0732 0.239 0.0154</size>
          </box>
        </geometry>
      </collision>
      <visual name="aileron_visual">
        <pose relative_to="base_link" degrees="true">0 0 0 0 0 0</pose>
        <geometry>
          <mesh>
            <uri>model://titan_cobra_vtol/meshes/titan_cobra_vtol.dae</uri>
            <submesh>
              <name>~CS_LA</name>
            </submesh>
          </mesh>
        </geometry>
        <material>
          <ambient>1 1 1</ambient>
          <diffuse>1 1 1</diffuse>
          <specular>0.5 0.5 0.5</specular>
          <pbr>
            <metal>
              <albedo_map>model://titan_cobra_vtol/meshes/TitanCobraTexture.tga</albedo_map>
              <roughness>0.5</roughness>
              <metalness>0.5</metalness> 
            </metal>
          </pbr>
        </material>
      </visual>
    </link>
    <joint name="left_aileron_joint" type="revolute">
      <pose relative_to="base_link" degrees="true">-0.115848 0.66957 0.056213 0 0 0</pose>
      <parent>base_link</parent>
      <child>left_aileron_link</child>
      <axis>
        <xyz>0 1 0</xyz>
        <limit>
          <lower>-0.78539816</lower>
          <upper>0.78539816</upper>
        </limit>
        <dynamics>
          <damping>0.004</damping>
        </dynamics>
      </axis>
    </joint>

    <link name="right_aileron_link">
      <pose relative_to="base_link" degrees="true">-0.115848 -0.66957 0.056213 0 0 0</pose>
      <inertial>
        <pose degrees="true">-0.035 0 0 0 0 0</pose>
        <mass>0.1</mass>
        <inertia>
          <ixx>0.000477985</ixx>
          <ixy>0</ixy>
          <iyy>4.66283E-05</iyy>
          <ixz>0</ixz>
          <iyz>0</iyz>
          <izz>0.00052066</izz>
        </inertia>
      </inertial>
      <collision name="aileron_collision">
        <pose degrees="true">-0.035 0 0 0 0 0</pose>
        <geometry>
          <box>
            <size>0.0732 0.239 0.0154</size>
          </box>
        </geometry>
      </collision>
      <visual name="aileron_visual">
        <pose relative_to="base_link" degrees="true">0 0 0 0 0 0</pose>
        <geometry>
          <mesh>
            <uri>model://titan_cobra_vtol/meshes/titan_cobra_vtol.dae</uri>
            <submesh>
              <name>~CS_RA</name>
            </submesh>
          </mesh>
        </geometry>
        <material>
          <ambient>1 1 1</ambient>
          <diffuse>1 1 1</diffuse>
          <specular>0.5 0.5 0.5</specular>
          <pbr>
            <metal>
              <albedo_map>model://titan_cobra_vtol/meshes/TitanCobraTexture.tga</albedo_map>
              <roughness>0.5</roughness>
              <metalness>0.5</metalness> 
            </metal>
          </pbr>
        </material>
      </visual>
    </link>
    <joint name="right_aileron_joint" type="revolute">
      <pose relative_to="base_link" degrees="true">-0.115848 -0.66957 0.056213 0 0 0</pose>
      <parent>base_link</parent>
      <child>right_aileron_link</child>
      <axis>
        <xyz>0 1 0</xyz>
        <limit>
          <lower>-0.78539816</lower>
          <upper>0.78539816</upper>
        </limit>
        <dynamics>
          <damping>0.004</damping>
        </dynamics>
      </axis>
    </joint>

    <link name="left_ruddervator_link">
      <pose relative_to="base_link" degrees="true">-0.718103 0.19396 0.127626 0 0 0</pose>
      <inertial>
        <pose degrees="true">-0.026 0 0 -45 0 0</pose>
        <mass>0.1</mass>
        <inertia>
          <ixx>0.000334932</ixx>
          <ixy>0</ixy>
          <iyy>2.86522E-05</iyy>
          <ixz>0</ixz>
          <iyz>0</iyz>
          <izz>0.000361594</izz>
        </inertia>
      </inertial>
      <collision name="ruddervator_collision">
        <pose degrees="true">-0.026 0 0 -45 0 0</pose>
        <geometry>
          <box>
            <size>0.057609 0.200181 0.01093</size>
          </box>
        </geometry>
      </collision>
      <visual name="ruddervator_visual">
        <pose relative_to="base_link" degrees="true">0 0 0 0 0 0</pose>
        <geometry>
          <mesh>
            <uri>model://titan_cobra_vtol/meshes/titan_cobra_vtol.dae</uri>
            <submesh>
              <name>~CS_LRV</name>
            </submesh>
          </mesh>
        </geometry>
        <material>
          <ambient>1 1 1</ambient>
          <diffuse>1 1 1</diffuse>
          <specular>0.5 0.5 0.5</specular>
          <pbr>
            <metal>
              <albedo_map>model://titan_cobra_vtol/meshes/TitanCobraTexture.tga</albedo_map>
              <roughness>0.5</roughness>
              <metalness>0.5</metalness> 
            </metal>
          </pbr>
        </material>
      </visual>
    </link>
    <joint name="left_ruddervator_joint" type="revolute">
      <pose relative_to="base_link" degrees="true">-0.718103 0.19396 0.127626 -45 0 0</pose>
      <parent>base_link</parent>
      <child>left_ruddervator_link</child>
      <axis>
        <xyz>0 1 0</xyz>
        <limit>
          <lower>-0.78539816</lower>
          <upper>0.78539816</upper>
        </limit>
        <dynamics>
          <damping>0.004</damping>
        </dynamics>
      </axis>
    </joint>

    <link name="right_ruddervator_link">
      <pose relative_to="base_link" degrees="true">-0.718103 -0.19396 0.127626 0 0 0</pose>
      <inertial>
        <pose degrees="true">-0.026 0 0 45 0 0</pose>
        <mass>0.1</mass>
        <inertia>
          <ixx>0.000334932</ixx>
          <ixy>0</ixy>
          <iyy>2.86522E-05</iyy>
          <ixz>0</ixz>
          <iyz>0</iyz>
          <izz>0.000361594</izz>
        </inertia>
      </inertial>
      <collision name="ruddervator_collision">
        <pose degrees="true">-0.026 0 0 45 0 0</pose>
        <geometry>
          <box>
            <size>0.057609 0.200181 0.01093</size>
          </box>
        </geometry>
      </collision>
      <visual name="ruddervator_visual">
        <pose relative_to="base_link" degrees="true">0 0 0 0 0 0</pose>
        <geometry>
          <mesh>
            <uri>model://titan_cobra_vtol/meshes/titan_cobra_vtol.dae</uri>
            <submesh>
              <name>~CS_RRV</name>
            </submesh>
          </mesh>
        </geometry>
        <material>
          <ambient>1 1 1</ambient>
          <diffuse>1 1 1</diffuse>
          <specular>0.5 0.5 0.5</specular>
          <pbr>
            <metal>
              <albedo_map>model://titan_cobra_vtol/meshes/TitanCobraTexture.tga</albedo_map>
              <roughness>0.5</roughness>
              <metalness>0.5</metalness> 
            </metal>
          </pbr>
        </material>
      </visual>
    </link>
    <joint name="right_ruddervator_joint" type="revolute">
      <pose relative_to="base_link" degrees="true">-0.718103 -0.19396 0.127626 45 0 0</pose>
      <parent>base_link</parent>
      <child>right_ruddervator_link</child>
      <axis>
        <xyz>0 1 0</xyz>
        <limit>
          <lower>-0.78539816</lower>
          <upper>0.78539816</upper>
        </limit>
        <dynamics>
          <damping>0.004</damping>
        </dynamics>
      </axis>
    </joint>

    <!-- motors -->
    <link name="motor_1_link">
      <pose relative_to="base_link">0.1875 -0.29 0.06 0 0 0</pose>
      <inertial>
        <pose>0 0 0 0 0 0</pose>
        <mass>0.025</mass>
        <inertia>
          <ixx>9.75e-06</ixx>
          <ixy>0</ixy>
          <ixz>0</ixz>
          <iyy>0.000166704</iyy>
          <iyz>0</iyz>
          <izz>0.000167604</izz>
        </inertia>
      </inertial>
      <collision name="spinner_collision">
        <pose relative_to="base_link" degrees="true">0 0 0 0 0 0</pose>
        <geometry>
          <cylinder>
            <length>0.005</length>
            <radius>0.105</radius>
          </cylinder>
        </geometry>
      </collision>
      <visual name="spinner_visual">
        <pose relative_to="base_link" degrees="true">0.22 0 -0.147 0 -90 0</pose>
        <geometry>
          <mesh>
            <uri>model://titan_cobra_vtol/meshes/titan_cobra_vtol.dae</uri>
            <submesh>
              <name>~CS_SPINNER1</name>
            </submesh>
          </mesh>
        </geometry>
        <material>
          <ambient>1 1 1</ambient>
          <diffuse>1 1 1</diffuse>
          <specular>0.5 0.5 0.5</specular>
          <pbr>
            <metal>
              <albedo_map>model://titan_cobra_vtol/meshes/TitanCobraTexture.tga</albedo_map>
              <roughness>0.5</roughness>
              <metalness>0.5</metalness> 
            </metal>
          </pbr>
        </material>
      </visual>
      <!-- <visual name="engine_visual">
        <pose relative_to="base_link" degrees="true">0.22 0 -0.147 0 -90 0</pose>
        <geometry>
          <mesh>
            <uri>model://titan_cobra_vtol/meshes/titan_cobra_vtol.dae</uri>
            <submesh>
              <name>~CS_ENGINE1</name>
            </submesh>
          </mesh>
        </geometry>
        <material>
          <ambient>1 1 1</ambient>
          <diffuse>1 1 1</diffuse>
          <specular>0.5 0.5 0.5</specular>
          <pbr>
            <metal>
              <albedo_map>model://titan_cobra_vtol/meshes/TitanCobraTexture.tga</albedo_map>
              <roughness>0.5</roughness>
              <metalness>0.5</metalness> 
            </metal>
          </pbr>
        </material>
      </visual> -->
      <visual name="prop_visual">
        <pose degrees="true">0 0 0.027 0 0 0</pose>
        <geometry>
          <mesh>
            <scale>1 1 1</scale>
            <uri>model://titan_cobra_vtol/meshes/prop_ccw.dae</uri>
          </mesh>
        </geometry>
         <material>
          <ambient>1 1 1</ambient>
          <diffuse>1 1 1</diffuse>
          <specular>1 1 1</specular>
          <pbr>
            <metal>
              <albedo_map>model://titan_cobra_vtol/materials/textures/metal_graphite/metal_graphite_basecolor.jpg</albedo_map>
              <metalness_map>model://titan_cobra_vtol/materials/textures/metal_graphite/metal_graphite_metallic.jpg</metalness_map>
              <normal_map>model://titan_cobra_vtol/materials/textures/metal_graphite/metal_graphite_normal.jpg</normal_map>
              <roughness_map>model://titan_cobra_vtol/materials/textures/metal_graphite/metal_graphite_roughness.jpg</roughness_map>
              <roughness>1.0</roughness>
              <metalness>1.0</metalness> 
            </metal>
          </pbr>
        </material>
      </visual>
    </link>
    <joint name="motor_1_joint" type="revolute">
      <pose relative_to="base_link">0.1875 -0.29 0.06 0 0 0</pose>
      <parent>base_link</parent>
      <child>motor_1_link</child>
      <axis>
        <xyz>0 0 1</xyz>
        <limit>
          <lower>-1e+16</lower>
          <upper>1e+16</upper>
        </limit>
        <dynamics>
          <damping>0.004</damping>
        </dynamics>
      </axis>
    </joint>

    <link name="motor_2_link">
      <pose relative_to="base_link">-0.367 0.29 0.06 0 0 0</pose>
      <inertial>
        <pose>0 0 0 0 0 0</pose>
        <mass>0.025</mass>
        <inertia>
          <ixx>9.75e-06</ixx>
          <ixy>0</ixy>
          <ixz>0</ixz>
          <iyy>0.000166704</iyy>
          <iyz>0</iyz>
          <izz>0.000167604</izz>
        </inertia>
      </inertial>
      <collision name="spinner_collision">
        <pose relative_to="base_link" degrees="true">0 0 0 0 0 0</pose>
        <geometry>
          <cylinder>
            <length>0.005</length>
            <radius>0.105</radius>
          </cylinder>
        </geometry>
      </collision>
      <visual name="spinner_visual">
        <pose relative_to="base_link" degrees="true">-0.335 0 0.412 0 -90 0</pose>
        <geometry>
          <mesh>
            <uri>model://titan_cobra_vtol/meshes/titan_cobra_vtol.dae</uri>
            <submesh>
              <name>~CS_SPINNER2</name>
            </submesh>
          </mesh>
        </geometry>
        <material>
          <ambient>1 1 1</ambient>
          <diffuse>1 1 1</diffuse>
          <specular>0.5 0.5 0.5</specular>
          <pbr>
            <metal>
              <albedo_map>model://titan_cobra_vtol/meshes/TitanCobraTexture.tga</albedo_map>
              <roughness>0.5</roughness>
              <metalness>0.5</metalness> 
            </metal>
          </pbr>
        </material>
      </visual>
      <!-- <visual name="engine_visual">
        <pose relative_to="base_link" degrees="true">-0.335 0 0.412 0 -90 0</pose>
        <geometry>
          <mesh>
            <uri>model://titan_cobra_vtol/meshes/titan_cobra_vtol.dae</uri>
            <submesh>
              <name>~CS_ENGINE2</name>
            </submesh>
          </mesh>
        </geometry>
        <material>
          <ambient>1 1 1</ambient>
          <diffuse>1 1 1</diffuse>
          <specular>0.5 0.5 0.5</specular>
          <pbr>
            <metal>
              <albedo_map>model://titan_cobra_vtol/meshes/TitanCobraTexture.tga</albedo_map>
              <roughness>0.5</roughness>
              <metalness>0.5</metalness> 
            </metal>
          </pbr>
        </material>
      </visual> -->
      <visual name="prop_visual">
        <pose degrees="true">0 0 0.027 0 0 0</pose>
        <geometry>
          <mesh>
            <scale>1 1 1</scale>
            <uri>model://titan_cobra_vtol/meshes/prop_ccw.dae</uri>
          </mesh>
        </geometry>
         <material>
          <ambient>1 1 1</ambient>
          <diffuse>1 1 1</diffuse>
          <specular>1 1 1</specular>
          <pbr>
            <metal>
              <albedo_map>model://titan_cobra_vtol/materials/textures/metal_graphite/metal_graphite_basecolor.jpg</albedo_map>
              <metalness_map>model://titan_cobra_vtol/materials/textures/metal_graphite/metal_graphite_metallic.jpg</metalness_map>
              <normal_map>model://titan_cobra_vtol/materials/textures/metal_graphite/metal_graphite_normal.jpg</normal_map>
              <roughness_map>model://titan_cobra_vtol/materials/textures/metal_graphite/metal_graphite_roughness.jpg</roughness_map>
              <roughness>1.0</roughness>
              <metalness>1.0</metalness> 
            </metal>
          </pbr>
        </material>
      </visual>
    </link>
    <joint name="motor_2_joint" type="revolute">
      <pose relative_to="base_link">-0.367 0.29 0.06 0 0 0</pose>
      <parent>base_link</parent>
      <child>motor_2_link</child>
      <axis>
        <xyz>0 0 1</xyz>
        <limit>
          <lower>-1e+16</lower>
          <upper>1e+16</upper>
        </limit>
        <dynamics>
          <damping>0.004</damping>
        </dynamics>
      </axis>
    </joint>

    <link name="motor_3_link">
      <pose relative_to="base_link">0.1875 0.29 0.06 0 0 0</pose>
      <inertial>
        <pose>0 0 0 0 0 0</pose>
        <mass>0.025</mass>
        <inertia>
          <ixx>9.75e-06</ixx>
          <ixy>0</ixy>
          <ixz>0</ixz>
          <iyy>0.000166704</iyy>
          <iyz>0</iyz>
          <izz>0.000167604</izz>
        </inertia>
      </inertial>
      <collision name="spinner_collision">
        <pose degrees="true">0 0 0 0 0 0</pose>
        <geometry>
          <cylinder>
            <length>0.005</length>
            <radius>0.105</radius>
          </cylinder>
        </geometry>
      </collision>
      <visual name="spinner_visual">
        <pose relative_to="base_link" degrees="true">0.22 0 -0.147 0 -90 0</pose>
        <geometry>
          <mesh>
            <uri>model://titan_cobra_vtol/meshes/titan_cobra_vtol.dae</uri>
            <submesh>
              <name>~CS_SPINNER3</name>
            </submesh>
          </mesh>
        </geometry>
        <material>
          <ambient>1 1 1</ambient>
          <diffuse>1 1 1</diffuse>
          <specular>0.5 0.5 0.5</specular>
          <pbr>
            <metal>
              <albedo_map>model://titan_cobra_vtol/meshes/TitanCobraTexture.tga</albedo_map>
              <roughness>0.5</roughness>
              <metalness>0.5</metalness> 
            </metal>
          </pbr>
        </material>
      </visual>
      <!-- <visual name="engine_visual">
        <pose relative_to="base_link" degrees="true">0.22 0 -0.147 0 -90 0</pose>
        <geometry>
          <mesh>
            <uri>model://titan_cobra_vtol/meshes/titan_cobra_vtol.dae</uri>
            <submesh>
              <name>~CS_ENGINE3</name>
            </submesh>
          </mesh>
        </geometry>
        <material>
          <ambient>1 1 1</ambient>
          <diffuse>1 1 1</diffuse>
          <specular>0.5 0.5 0.5</specular>
          <pbr>
            <metal>
              <albedo_map>model://titan_cobra_vtol/meshes/TitanCobraTexture.tga</albedo_map>
              <roughness>0.5</roughness>
              <metalness>0.5</metalness> 
            </metal>
          </pbr>
        </material>
      </visual> -->
      <visual name="prop_visual">
        <pose degrees="true">0 0 0.027 0 0 0</pose>
        <geometry>
          <mesh>
            <scale>1 1 1</scale>
            <uri>model://titan_cobra_vtol/meshes/prop_cw.dae</uri>
          </mesh>
        </geometry>
         <material>
          <ambient>1 1 1</ambient>
          <diffuse>1 1 1</diffuse>
          <specular>1 1 1</specular>
          <pbr>
            <metal>
              <albedo_map>model://titan_cobra_vtol/materials/textures/metal_graphite/metal_graphite_basecolor.jpg</albedo_map>
              <metalness_map>model://titan_cobra_vtol/materials/textures/metal_graphite/metal_graphite_metallic.jpg</metalness_map>
              <normal_map>model://titan_cobra_vtol/materials/textures/metal_graphite/metal_graphite_normal.jpg</normal_map>
              <roughness_map>model://titan_cobra_vtol/materials/textures/metal_graphite/metal_graphite_roughness.jpg</roughness_map>
              <roughness>1.0</roughness>
              <metalness>1.0</metalness> 
            </metal>
          </pbr>
        </material>
      </visual>
    </link>
    <joint name="motor_3_joint" type="revolute">
      <pose relative_to="base_link">0.1875 0.29 0.06 0 0 0</pose>
      <parent>base_link</parent>
      <child>motor_3_link</child>
      <axis>
        <xyz>0 0 1</xyz>
        <limit>
          <lower>-1e+16</lower>
          <upper>1e+16</upper>
        </limit>
        <dynamics>
          <damping>0.004</damping>
        </dynamics>
      </axis>
    </joint>

    <link name="motor_4_link">
      <pose relative_to="base_link">-0.367 -0.29 0.06 0 0 0</pose>
      <inertial>
        <pose>0 0 0 0 0 0</pose>
        <mass>0.025</mass>
        <inertia>
          <ixx>9.75e-06</ixx>
          <ixy>0</ixy>
          <ixz>0</ixz>
          <iyy>0.000166704</iyy>
          <iyz>0</iyz>
          <izz>0.000167604</izz>
        </inertia>
      </inertial>
      <collision name="spinner_collision">
        <pose relative_to="base_link" degrees="true">0 0 0 0 0 0</pose>
        <geometry>
          <cylinder>
            <length>0.005</length>
            <radius>0.105</radius>
          </cylinder>
        </geometry>
      </collision>
      <visual name="spinner_visual">
        <pose relative_to="base_link" degrees="true">-0.335 0 0.412 0 -90 0</pose>
        <geometry>
          <mesh>
            <uri>model://titan_cobra_vtol/meshes/titan_cobra_vtol.dae</uri>
            <submesh>
              <name>~CS_SPINNER4</name>
            </submesh>
          </mesh>
        </geometry>
        <material>
          <ambient>1 1 1</ambient>
          <diffuse>1 1 1</diffuse>
          <specular>0.5 0.5 0.5</specular>
          <pbr>
            <metal>
              <albedo_map>model://titan_cobra_vtol/meshes/TitanCobraTexture.tga</albedo_map>
              <roughness>0.5</roughness>
              <metalness>0.5</metalness> 
            </metal>
          </pbr>
        </material>
      </visual>
      <!-- <visual name="engine_visual">
        <pose relative_to="base_link" degrees="true">-0.335 0 0.412 0 -90 0</pose>
        <geometry>
          <mesh>
            <uri>model://titan_cobra_vtol/meshes/titan_cobra_vtol.dae</uri>
            <submesh>
              <name>~CS_ENGINE4</name>
            </submesh>
          </mesh>
        </geometry>
        <material>
          <ambient>1 1 1</ambient>
          <diffuse>1 1 1</diffuse>
          <specular>0.5 0.5 0.5</specular>
          <pbr>
            <metal>
              <albedo_map>model://titan_cobra_vtol/meshes/TitanCobraTexture.tga</albedo_map>
              <roughness>0.5</roughness>
              <metalness>0.5</metalness> 
            </metal>
          </pbr>
        </material>
      </visual> -->
      <visual name="prop_visual">
        <pose degrees="true">0 0 0.027 0 0 0</pose>
        <geometry>
          <mesh>
            <scale>1 1 1</scale>
            <uri>model://titan_cobra_vtol/meshes/prop_cw.dae</uri>
          </mesh>
        </geometry>
         <material>
          <ambient>1 1 1</ambient>
          <diffuse>1 1 1</diffuse>
          <specular>1 1 1</specular>
          <pbr>
            <metal>
              <albedo_map>model://titan_cobra_vtol/materials/textures/metal_graphite/metal_graphite_basecolor.jpg</albedo_map>
              <metalness_map>model://titan_cobra_vtol/materials/textures/metal_graphite/metal_graphite_metallic.jpg</metalness_map>
              <normal_map>model://titan_cobra_vtol/materials/textures/metal_graphite/metal_graphite_normal.jpg</normal_map>
              <roughness_map>model://titan_cobra_vtol/materials/textures/metal_graphite/metal_graphite_roughness.jpg</roughness_map>
              <roughness>1.0</roughness>
              <metalness>1.0</metalness> 
            </metal>
          </pbr>
        </material>
      </visual>
    </link>
    <joint name="motor_4_joint" type="revolute">
      <pose relative_to="base_link">-0.367 -0.29 0.06 0 0 0</pose>
      <parent>base_link</parent>
      <child>motor_4_link</child>
      <axis>
        <xyz>0 0 1</xyz>
        <limit>
          <lower>-1e+16</lower>
          <upper>1e+16</upper>
        </limit>
        <dynamics>
          <damping>0.004</damping>
        </dynamics>
      </axis>
    </joint>

    <link name="motor_5_link">
      <pose relative_to="base_link" degrees="true">-0.268 0 0.03 0 -90 0</pose>
      <inertial>
        <pose>0 0 0 0 0 0</pose>
        <mass>0.025</mass>
        <inertia>
          <ixx>9.75e-06</ixx>
          <ixy>0</ixy>
          <ixz>0</ixz>
          <iyy>0.000166704</iyy>
          <iyz>0</iyz>
          <izz>0.000167604</izz>
        </inertia>
      </inertial>
      <collision name="spinner_collision">
        <pose relative_to="base_link" degrees="true">0 0 0 0 0 0</pose>
        <geometry>
          <cylinder>
            <length>0.005</length>
            <radius>0.105</radius>
          </cylinder>
        </geometry>
      </collision>
      <visual name="spinner_visual">
        <pose relative_to="base_link" degrees="true">0 0 0 0 0 0</pose>
        <geometry>
          <mesh>
            <uri>model://titan_cobra_vtol/meshes/titan_cobra_vtol.dae</uri>
            <submesh>
              <name>~CS_SPINNER5</name>
            </submesh>
          </mesh>
        </geometry>
        <material>
          <ambient>1 1 1</ambient>
          <diffuse>1 1 1</diffuse>
          <specular>0.5 0.5 0.5</specular>
          <pbr>
            <metal>
              <albedo_map>model://titan_cobra_vtol/meshes/TitanCobraTexture.tga</albedo_map>
              <roughness>0.5</roughness>
              <metalness>0.5</metalness> 
            </metal>
          </pbr>
        </material>
      </visual>
      <!-- <visual name="engine_visual">
        <pose relative_to="base_link" degrees="true">0 0 0 0 0 0</pose>
        <geometry>
          <mesh>
            <uri>model://titan_cobra_vtol/meshes/titan_cobra_vtol.dae</uri>
            <submesh>
              <name>~CS_ENGINE5</name>
            </submesh>
          </mesh>
        </geometry>
        <material>
          <ambient>1 1 1</ambient>
          <diffuse>1 1 1</diffuse>
          <specular>0.5 0.5 0.5</specular>
          <pbr>
            <metal>
              <albedo_map>model://titan_cobra_vtol/meshes/TitanCobraTexture.tga</albedo_map>
              <roughness>0.5</roughness>
              <metalness>0.5</metalness> 
            </metal>
          </pbr>
        </material>
      </visual> -->
      <visual name="prop_visual">
        <pose degrees="true">0 0 0.027 0 180 0</pose>
        <geometry>
          <mesh>
            <scale>1 1 1</scale>
            <uri>model://titan_cobra_vtol/meshes/prop_ccw.dae</uri>
          </mesh>
        </geometry>
         <material>
          <ambient>1 1 1</ambient>
          <diffuse>1 1 1</diffuse>
          <specular>1 1 1</specular>
          <pbr>
            <metal>
              <albedo_map>model://titan_cobra_vtol/materials/textures/metal_graphite/metal_graphite_basecolor.jpg</albedo_map>
              <metalness_map>model://titan_cobra_vtol/materials/textures/metal_graphite/metal_graphite_metallic.jpg</metalness_map>
              <normal_map>model://titan_cobra_vtol/materials/textures/metal_graphite/metal_graphite_normal.jpg</normal_map>
              <roughness_map>model://titan_cobra_vtol/materials/textures/metal_graphite/metal_graphite_roughness.jpg</roughness_map>
              <roughness>1.0</roughness>
              <metalness>1.0</metalness> 
            </metal>
          </pbr>
        </material>
      </visual>
    </link>
    <joint name="motor_5_joint" type="revolute">
      <pose relative_to="base_link" degrees="true">-0.268 0 0.03 0 -90 0</pose>
      <parent>base_link</parent>
      <child>motor_5_link</child>
      <axis>
        <xyz>0 0 1</xyz>
        <limit>
          <lower>-1e+16</lower>
          <upper>1e+16</upper>
        </limit>
        <dynamics>
          <damping>0.004</damping>
        </dynamics>
      </axis>
    </joint>

    <!-- sensors -->
    <link name="imu_link">
      <inertial>
        <pose>0 0 0 0 0 0</pose>
        <mass>0.15</mass>
        <inertia>
          <ixx>0.00002</ixx>
          <ixy>0</ixy>
          <ixz>0</ixz>
          <iyy>0.00002</iyy>
          <iyz>0</iyz>
          <izz>0.00002</izz>
        </inertia>
      </inertial>
      <sensor name="imu_sensor" type="imu">
        <pose degrees="true">0 0 0 180 0 0</pose>
        <always_on>1</always_on>
        <update_rate>1000.0</update_rate>
      </sensor>
    </link>
    <joint name="imu_joint" type="revolute">
      <child>imu_link</child>
      <parent>base_link</parent>
      <axis>
        <xyz>0 0 1</xyz>
        <limit>
          <lower>0</lower>
          <upper>0</upper>
        </limit>
        <dynamics>
          <damping>1.0</damping>
        </dynamics>
      </axis>
    </joint>

    <!-- plugins -->
    <plugin name="gz::sim::systems::JointStatePublisher"
      filename="gz-sim-joint-state-publisher-system">
    </plugin>

    <plugin name="gz::sim::systems::JointPositionController"
        filename="gz-sim-joint-position-controller-system">
      <joint_name>left_aileron_joint</joint_name>
      <topic>/left_aileron/cmd_pos</topic>
      <use_force_commands>1</use_force_commands>
      <p_gain>1</p_gain>
      <i_gain>0</i_gain>
      <d_gain>0.1</d_gain>
      <i_max>1</i_max>
      <i_min>-1</i_min>
      <cmd_max>5</cmd_max>
      <cmd_min>-5</cmd_min>
    </plugin>
    
    <plugin name="gz::sim::systems::JointPositionController"
        filename="gz-sim-joint-position-controller-system">
      <joint_name>right_aileron_joint</joint_name>
      <topic>/right_aileron/cmd_pos</topic>
      <use_force_commands>1</use_force_commands>
      <p_gain>1</p_gain>
      <i_gain>0</i_gain>
      <d_gain>0.1</d_gain>
      <i_max>1</i_max>
      <i_min>-1</i_min>
      <cmd_max>5</cmd_max>
      <cmd_min>-5</cmd_min>
    </plugin>

    <plugin name="gz::sim::systems::JointPositionController"
        filename="gz-sim-joint-position-controller-system">
      <joint_name>left_ruddervator_joint</joint_name>
      <topic>/left_ruddervator/cmd_pos</topic>
      <use_force_commands>1</use_force_commands>
      <p_gain>1</p_gain>
      <i_gain>0</i_gain>
      <d_gain>0.1</d_gain>
      <i_max>1</i_max>
      <i_min>-1</i_min>
      <cmd_max>5</cmd_max>
      <cmd_min>-5</cmd_min>
    </plugin>

    <plugin name="gz::sim::systems::JointPositionController"
        filename="gz-sim-joint-position-controller-system">
      <joint_name>right_ruddervator_joint</joint_name>
      <topic>/right_ruddervator/cmd_pos</topic>
      <use_force_commands>1</use_force_commands>
      <p_gain>1</p_gain>
      <i_gain>0</i_gain>
      <d_gain>0.1</d_gain>
      <i_max>1</i_max>
      <i_min>-1</i_min>
      <cmd_max>5</cmd_max>
      <cmd_min>-5</cmd_min>
    </plugin>

    <plugin name="gz::sim::systems::JointController"
      filename="gz-sim-joint-controller-system">
      <joint_name>motor_1_joint</joint_name>
      <topic>/motor_1/cmd_vel</topic>
      <initial_velocity>0.0</initial_velocity>
      <use_force_commands>1</use_force_commands>
      <p_gain>0.2</p_gain>
      <i_gain>0.0</i_gain>
      <d_gain>0.0</d_gain>
      <i_max>1</i_max>
      <i_min>-1</i_min>
      <cmd_max>5</cmd_max>
      <cmd_min>-5</cmd_min>
    </plugin>

    <plugin name="gz::sim::systems::JointController"
      filename="gz-sim-joint-controller-system">
      <joint_name>motor_2_joint</joint_name>
      <topic>/motor_2/cmd_vel</topic>
      <initial_velocity>0.0</initial_velocity>
      <use_force_commands>1</use_force_commands>
      <p_gain>0.2</p_gain>
      <i_gain>0.0</i_gain>
      <d_gain>0.0</d_gain>
      <i_max>1</i_max>
      <i_min>-1</i_min>
      <cmd_max>5</cmd_max>
      <cmd_min>-5</cmd_min>
    </plugin>

    <plugin name="gz::sim::systems::JointController"
      filename="gz-sim-joint-controller-system">
      <joint_name>motor_3_joint</joint_name>
      <topic>/motor_3/cmd_vel</topic>
      <initial_velocity>0.0</initial_velocity>
      <use_force_commands>1</use_force_commands>
      <p_gain>0.2</p_gain>
      <i_gain>0.0</i_gain>
      <d_gain>0.0</d_gain>
      <i_max>1</i_max>
      <i_min>-1</i_min>
      <cmd_max>5</cmd_max>
      <cmd_min>-5</cmd_min>
    </plugin>

    <plugin name="gz::sim::systems::JointController"
      filename="gz-sim-joint-controller-system">
      <joint_name>motor_4_joint</joint_name>
      <topic>/motor_4/cmd_vel</topic>
      <initial_velocity>0.0</initial_velocity>
      <use_force_commands>1</use_force_commands>
      <p_gain>0.2</p_gain>
      <i_gain>0.0</i_gain>
      <d_gain>0.0</d_gain>
      <i_max>1</i_max>
      <i_min>-1</i_min>
      <cmd_max>5</cmd_max>
      <cmd_min>-5</cmd_min>
    </plugin>

    <plugin name="gz::sim::systems::JointController"
      filename="gz-sim-joint-controller-system">
      <joint_name>motor_5_joint</joint_name>
      <topic>/motor_5/cmd_vel</topic>
      <initial_velocity>0.0</initial_velocity>
      <use_force_commands>1</use_force_commands>
      <p_gain>0.2</p_gain>
      <i_gain>0.0</i_gain>
      <d_gain>0.0</d_gain>
      <i_max>1</i_max>
      <i_min>-1</i_min>
      <cmd_max>5</cmd_max>
      <cmd_min>-5</cmd_min>
    </plugin>

    <!-- lift-drag from iris wih area increased -->
    <plugin name="gz::sim::systems::LiftDrag"
      filename="gz-sim-lift-drag-system">
      <a0>0.3</a0>
      <alpha_stall>1.4</alpha_stall>
      <cla>4.2500</cla>
      <cda>0.10</cda>
      <cma>0.0</cma>
      <cla_stall>-0.025</cla_stall>
      <cda_stall>0.0</cda_stall>
      <cma_stall>0.0</cma_stall>
      <area>0.003</area>
      <air_density>1.2041</air_density>
      <cp>0.084 0 0</cp>
      <forward>0 1 0</forward>
      <upward>0 0 1</upward>
      <link_name>motor_1_link</link_name>
    </plugin>
    <plugin name="gz::sim::systems::LiftDrag"
      filename="gz-sim-lift-drag-system">
      <a0>0.3</a0>
      <alpha_stall>1.4</alpha_stall>
      <cla>4.2500</cla>
      <cda>0.10</cda>
      <cma>0.0</cma>
      <cla_stall>-0.025</cla_stall>
      <cda_stall>0.0</cda_stall>
      <cma_stall>0.0</cma_stall>
      <area>0.003</area>
      <air_density>1.2041</air_density>
      <cp>-0.084 0 0</cp>
      <forward>0 -1 0</forward>
      <upward>0 0 1</upward>
      <link_name>motor_1_link</link_name>
    </plugin>

    <plugin name="gz::sim::systems::LiftDrag"
      filename="gz-sim-lift-drag-system">
      <a0>0.3</a0>
      <alpha_stall>1.4</alpha_stall>
      <cla>4.2500</cla>
      <cda>0.10</cda>
      <cma>0.0</cma>
      <cla_stall>-0.025</cla_stall>
      <cda_stall>0.0</cda_stall>
      <cma_stall>0.0</cma_stall>
      <area>0.003</area>
      <air_density>1.2041</air_density>
      <cp>0.084 0 0</cp>
      <forward>0 1 0</forward>
      <upward>0 0 1</upward>
      <link_name>motor_2_link</link_name>
    </plugin>
    <plugin name="gz::sim::systems::LiftDrag"
      filename="gz-sim-lift-drag-system">
      <a0>0.3</a0>
      <alpha_stall>1.4</alpha_stall>
      <cla>4.2500</cla>
      <cda>0.10</cda>
      <cma>0.0</cma>
      <cla_stall>-0.025</cla_stall>
      <cda_stall>0.0</cda_stall>
      <cma_stall>0.0</cma_stall>
      <area>0.003</area>
      <air_density>1.2041</air_density>
      <cp>-0.084 0 0</cp>
      <forward>0 -1 0</forward>
      <upward>0 0 1</upward>
      <link_name>motor_2_link</link_name>
    </plugin>

    <plugin name="gz::sim::systems::LiftDrag"
      filename="gz-sim-lift-drag-system">
      <a0>0.3</a0>
      <alpha_stall>1.4</alpha_stall>
      <cla>4.2500</cla>
      <cda>0.10</cda>
      <cma>0.0</cma>
      <cla_stall>-0.025</cla_stall>
      <cda_stall>0.0</cda_stall>
      <cma_stall>0.0</cma_stall>
      <area>0.003</area>
      <air_density>1.2041</air_density>
      <cp>0.084 0 0</cp>
      <forward>0 -1 0</forward>
      <upward>0 0 1</upward>
      <link_name>motor_3_link</link_name>
    </plugin>
    <plugin name="gz::sim::systems::LiftDrag"
      filename="gz-sim-lift-drag-system">
      <a0>0.3</a0>
      <alpha_stall>1.4</alpha_stall>
      <cla>4.2500</cla>
      <cda>0.10</cda>
      <cma>0.0</cma>
      <cla_stall>-0.025</cla_stall>
      <cda_stall>0.0</cda_stall>
      <cma_stall>0.0</cma_stall>
      <area>0.003</area>
      <air_density>1.2041</air_density>
      <cp>-0.084 0 0</cp>
      <forward>0 1 0</forward>
      <upward>0 0 1</upward>
      <link_name>motor_3_link</link_name>
    </plugin>

    <plugin name="gz::sim::systems::LiftDrag"
      filename="gz-sim-lift-drag-system">
      <a0>0.3</a0>
      <alpha_stall>1.4</alpha_stall>
      <cla>4.2500</cla>
      <cda>0.10</cda>
      <cma>0.0</cma>
      <cla_stall>-0.025</cla_stall>
      <cda_stall>0.0</cda_stall>
      <cma_stall>0.0</cma_stall>
      <area>0.003</area>
      <air_density>1.2041</air_density>
      <cp>0.084 0 0</cp>
      <forward>0 -1 0</forward>
      <upward>0 0 1</upward>
      <link_name>motor_4_link</link_name>
    </plugin>
    <plugin name="gz::sim::systems::LiftDrag"
      filename="gz-sim-lift-drag-system">
      <a0>0.3</a0>
      <alpha_stall>1.4</alpha_stall>
      <cla>4.2500</cla>
      <cda>0.10</cda>
      <cma>0.0</cma>
      <cla_stall>-0.025</cla_stall>
      <cda_stall>0.0</cda_stall>
      <cma_stall>0.0</cma_stall>
      <area>0.003</area>
      <air_density>1.2041</air_density>
      <cp>-0.084 0 0</cp>
      <forward>0 1 0</forward>
      <upward>0 0 1</upward>
      <link_name>motor_4_link</link_name>
    </plugin>

    <plugin name="ArduPilotPlugin" filename="ArduPilotPlugin">
      <!-- Connection -->
      <fdm_addr>127.0.0.1</fdm_addr>
      <fdm_port_in>9002</fdm_port_in>
      <connectionTimeoutMaxCount>5</connectionTimeoutMaxCount>
      <lock_step>1</lock_step>
      <have_32_channels>0</have_32_channels>

      <!-- Frame transformations -->
      <modelXYZToAirplaneXForwardZDown degrees="true">0 0 0 180 0 0</modelXYZToAirplaneXForwardZDown>
      <gazeboXYZToNED degrees="true">0 0 0 180 0 90</gazeboXYZToNED>

      <!-- Sensors -->
      <imuName>imu_sensor</imuName>

      <!-- 
          SERVO1_FUNCTION   4 (Aileron) +/- 30 deg
          SERVO1_MAX        2000
          SERVO1_MIN        1000
          SERVO1_REVERSED   0
          SERVO1_TRIM       1500
       -->
      <control channel="0">
        <jointName>left_aileron_joint</jointName>
        <multiplier>-1.0471976</multiplier>
        <offset>-0.5</offset>
        <servo_max>2000</servo_max>
        <servo_min>1000</servo_min>
        <type>COMMAND</type>
        <cmd_topic>/left_aileron/cmd_pos</cmd_topic>
      </control>

      <control channel="0">
        <jointName>right_aileron_joint</jointName>
        <multiplier>1.0471976</multiplier>
        <offset>-0.5</offset>
        <servo_max>2000</servo_max>
        <servo_min>1000</servo_min>
        <type>COMMAND</type>
        <cmd_topic>/right_aileron/cmd_pos</cmd_topic>
      </control>

      <!-- 
          SERVO2_FUNCTION   80 (Right V-Tail = Left A-Tail) +/- 30 deg
          SERVO2_MAX        2000
          SERVO2_MIN        1000
          SERVO2_REVERSED   0
          SERVO2_TRIM       1500
       -->
      <control channel="1">
        <jointName>left_ruddervator_joint</jointName>
        <multiplier>1.0471976</multiplier>
        <offset>-0.5</offset>
        <servo_max>2000</servo_max>
        <servo_min>1000</servo_min>
        <type>COMMAND</type>
        <cmd_topic>/left_ruddervator/cmd_pos</cmd_topic>
      </control>

      <!-- 
          SERVO3_FUNCTION   70 (Throttle)
          SERVO3_MAX        2000
          SERVO3_MIN        1000
          SERVO3_REVERSED   0
          SERVO3_TRIM       1000
       -->
      <control channel="2"> 
        <jointName>motor_5_joint</jointName>
        <multiplier>900</multiplier>
        <offset>0</offset>
        <servo_max>2000</servo_max>
        <servo_min>1000</servo_min>
        <type>COMMAND</type>
        <cmd_topic>/motor_5/cmd_vel</cmd_topic>
      </control>

      <!-- 
          SERVO4_FUNCTION   79 (Left V-Tail = Right A-Tail) +/- 30 deg
          SERVO4_MAX        2000
          SERVO4_MIN        1000
          SERVO4_REVERSED   0
          SERVO4_TRIM       1500
       -->
      <control channel="3">
        <jointName>right_ruddervator_joint</jointName>
        <multiplier>1.0471976</multiplier>
        <offset>-0.5</offset>
        <servo_max>2000</servo_max>
        <servo_min>1000</servo_min>
        <type>COMMAND</type>
        <cmd_topic>/right_ruddervator/cmd_pos</cmd_topic>
      </control>

      <!-- 
          SERVO5_FUNCTION   33 (Motor1) Front Right CCW
          SERVO5_MAX        2000
          SERVO5_MIN        1000
          SERVO5_REVERSED   0
          SERVO5_TRIM       1500
       -->
      <control channel="4">
        <jointName>motor_1_joint</jointName>
        <useForce>1</useForce>
        <multiplier>900</multiplier>
        <offset>0</offset>
        <servo_max>2000</servo_max>
        <servo_min>1000</servo_min>
        <type>COMMAND</type>
        <cmd_topic>/motor_1/cmd_vel</cmd_topic>
      </control>

      <!-- 
          SERVO6_FUNCTION   34 (Motor2) Rear Left CCW
          SERVO6_MAX        2000
          SERVO6_MIN        1000
          SERVO6_REVERSED   0
          SERVO6_TRIM       1500
       -->
      <control channel="5">
        <jointName>motor_2_joint</jointName>
        <useForce>1</useForce>
        <multiplier>900</multiplier>
        <offset>0</offset>
        <servo_max>2000</servo_max>
        <servo_min>1000</servo_min>
        <type>COMMAND</type>
        <cmd_topic>/motor_2/cmd_vel</cmd_topic>
      </control>

      <!-- 
          SERVO7_FUNCTION   35 (Motor3) Front Left CW
          SERVO7_MAX        2000
          SERVO7_MIN        1000
          SERVO7_REVERSED   0
          SERVO7_TRIM       1500
       -->
      <control channel="6">
        <jointName>motor_3_joint</jointName>
        <useForce>1</useForce>
        <multiplier>-900</multiplier>
        <offset>0</offset>
        <servo_max>2000</servo_max>
        <servo_min>1000</servo_min>
        <type>COMMAND</type>
        <cmd_topic>/motor_3/cmd_vel</cmd_topic>
      </control>

      <!-- 
          SERVO8_FUNCTION   36 (Motor4) Rear Right CW
          SERVO8_MAX        2000
          SERVO8_MIN        1000
          SERVO8_REVERSED   0
          SERVO8_TRIM       1500
       -->
      <control channel="7">
        <jointName>motor_4_joint</jointName>
        <useForce>1</useForce>
        <multiplier>-900</multiplier>
        <offset>0</offset>
        <servo_max>2000</servo_max>
        <servo_min>1000</servo_min>
        <type>COMMAND</type>
        <cmd_topic>/motor_4/cmd_vel</cmd_topic>
      </control>

    </plugin>

  </model>
</sdf>