<?xml version='1.0'?>
<!--
  Issues

  1. <gazeboXYZToNED>0 0 0 180 0 90</gazeboXYZToNED>
  
  Missing degrees="true", should be 
  
    <gazeboXYZToNED degrees="true">0 0 0 180 0 90</gazeboXYZToNED>

  2. IMU sensor rotated 90 about z
    
    <pose>0 0 0 3.141593 0 -1.5708</pose>

    Should be rotated 180 about x-axis so z points down

    <pose degrees="true">0 0 0 180 0 0</pose>

   3. velocity controllers. I gain will have no effect because
      it is clamped to [0, 0]. Prob not needed anyway.

      max output from controller is low (+/- 3 N) which is low for
      a 15 kg model. may be unresponsive under load.

    <i_gain>0.1</i_gain>
    <d_gain>0</d_gain>
    <i_max>0</i_max>
    <i_min>0</i_min>
    <cmd_max>3</cmd_max>
    <cmd_min>-3</cmd_min>

  4. <script> elements are not valid in Gazebo Garden materials

  5. Set ports correctly

    Replace

      <fdm_port_in>9022</fdm_port_in>

    With

      <fdm_port_in>9002</fdm_port_in>

    Remove

      <fdm_port_out>9023</fdm_port_out>

  6. The rotor orientation is correct for a quad copter

    rotor_0   CCW   front right
    rotor_1   CCW   back left
    rotor_2   CW    front left
    rotor_3   CW    back right

    The problem is that the frame visuals and collisions is rotated wrt to this. 


 -->
<sdf version='1.9'>
  <model name='anna1'>
    <!-- <pose>0 0 0.5 0 0 0</pose> -->
    <self_collide>0</self_collide>
    <static>0</static>
    <link name="base_link">
      <velocity_decay>
        <linear>0.0</linear>
        <angular>0.0</angular>
      </velocity_decay>
      <inertial>
        <mass>15.5</mass>
        <inertia>
          <ixx>0.4</ixx>
          <ixy>0</ixy>
          <ixz>0</ixz>
          <iyy>0.4</iyy>
          <iyz>0</iyz>
          <izz>0.8</izz>
        </inertia>
        <pose>0 0 0 0 0 0</pose>
      </inertial>
      <gravity>1</gravity>

      <!-- <visual name="base_link_visual">
        <pose>0 0 .025 0 0 0</pose>
        <geometry>
          <mesh>
            <scale>1 1 1</scale>
            <uri>model://anna_1/meshes/anna.stl</uri>
          </mesh>
        </geometry>
        <material>
          <ambient>0.2 0.2 0.2 1.0</ambient>
          <diffuse>0.2 0.2 0.2 1.0</diffuse>
        </material>
      </visual> -->

      <visual name="base_link_visual_0">
        <pose>0 -0.03 .127 0 0 0</pose>
        <geometry>
          <box>
            <size>0.35355339059327373 0.443553 0.2</size>
          </box>
        </geometry>
        <material>
          <ambient>0.2 0.2 0.2 1.0</ambient>
          <diffuse>0.2 0.2 0.2 1.0</diffuse>
        </material>
      </visual>
      <visual name='base_link_visual_2'>
        <pose>-0.24 -0.025 -0.25 0.35 0 1.5708</pose>
        <geometry>
          <box>
            <size>0.015 0.015 0.45</size>
          </box>
        </geometry>
        <material>
          <ambient>0.2 0.2 0.2 1.0</ambient>
          <diffuse>0.2 0.2 0.2 1.0</diffuse>
        </material>
      </visual>
      <visual name='base_link_visual_1'>
        <pose>0.22 -0.025 -0.25 -0.35 0 1.5708</pose>
        <geometry>
          <box>
            <size>0.015 0.015 0.45</size>
          </box>
        </geometry>
        <material>
          <ambient>0.2 0.2 0.2 1.0</ambient>
          <diffuse>0.2 0.2 0.2 1.0</diffuse>
        </material>
      </visual>
      <visual name='base_link_visual_3'>
        <pose>-0.31 -0.022 -0.465 0 0 1.5708</pose>
        <geometry>
          <box>
            <size>0.5 0.015 0.015</size>
          </box>
        </geometry>
        <material>
          <ambient>0.2 0.2 0.2 1.0</ambient>
          <diffuse>0.2 0.2 0.2 1.0</diffuse>
        </material>
      </visual>
      <visual name='base_link_visual_4'>
        <pose>0.3 -0.022 -0.465 0 0 1.5708</pose>
        <geometry>
          <box>
            <size>0.5 0.015 0.015</size>
          </box>
        </geometry>
        <material>
          <ambient>0.2 0.2 0.2 1.0</ambient>
          <diffuse>0.2 0.2 0.2 1.0</diffuse>
        </material>
      </visual>
      
      <collision name="base_link_collision_0">
        <pose>0 -0.03 .127 0 0 0</pose>
        <geometry>
          <box>
            <size>0.35355339059327373 0.443553 0.2</size>
          </box>
        </geometry>
        <surface>
          <contact>
            <ode>
              <min_depth>0.001</min_depth>
              <max_vel>0</max_vel>
            </ode>
          </contact>
          <friction>
             <ode>
               <mu>1000</mu>
               <mu2>500</mu2>
             </ode>
          </friction>
        </surface>
      </collision>
      <collision name='base_link_collision_1'>
        <pose>0.22 -0.025 -0.25 -0.35 0 1.5708</pose>
        <geometry>
          <box>
            <size>0.015 0.015 0.45</size>
          </box>
        </geometry>
        <surface>
          <contact>
            <ode>
              <min_depth>0.001</min_depth>
              <max_vel>0</max_vel>
            </ode>
          </contact>
          <friction>
             <ode>
               <mu>1000</mu>
               <mu2>500</mu2>
             </ode>
          </friction>
        </surface>
      </collision>
      <collision name='base_link_collision_2'>
        <pose>-0.24 -0.025 -0.25 0.35 0 1.5708</pose>
        <geometry>
          <box>
            <size>0.015 0.015 0.45</size>
          </box>
        </geometry>
        <surface>
          <contact>
            <ode>
              <min_depth>0.001</min_depth>
              <max_vel>0</max_vel>
            </ode>
          </contact>
          <friction>
             <ode>
               <mu>1000</mu>
               <mu2>500</mu2>
             </ode>
          </friction>
        </surface>
      </collision>
      <collision name='base_link_collision_3'>
        <pose>-0.31 -0.022 -0.465 0 0 1.5708</pose>
        <geometry>
          <box>
            <size>0.5 0.015 0.015</size>
          </box>
        </geometry>
        <surface>
          <contact>
            <ode>
              <min_depth>0.001</min_depth>
              <max_vel>0</max_vel>
            </ode>
          </contact>
          <friction>
             <ode>
               <mu>1000</mu>
               <mu2>500</mu2>
             </ode>
          </friction>
        </surface>
      </collision>
      <collision name='base_link_collision_4'>
        <pose>0.3 -0.022 -0.465 0 0 1.5708</pose>
        <geometry>
          <box>
            <size>0.5 0.015 0.015</size>
          </box>
        </geometry>
        <surface>
          <contact>
            <ode>
              <min_depth>0.001</min_depth>
              <max_vel>0</max_vel>
            </ode>
          </contact>
          <friction>
             <ode>
               <mu>1000</mu>
               <mu2>500</mu2>
             </ode>
          </friction>
        </surface>
      </collision>

      <sensor name="imu_sensor" type="imu">
        <pose degrees="true">0 0 0 180 0 0</pose>
        <always_on>1</always_on>
        <update_rate>1000</update_rate>
      </sensor>
    </link>
    <!-- <link name='battery_0'>
      <pose>0.05 0.09 -0.08 0 0 1.5708</pose>
      <gravity>1</gravity>
      <self_collide>0</self_collide>
      <velocity_decay/>
      <inertial>
        <mass>4.25</mass>
        <inertia>
          <ixx>0.0272</ixx>
          <ixy>0</ixy>
          <ixz>0</ixz>
          <iyy>0.095625</iyy>
          <iyz>0</iyz>
          <izz>0.212825</izz>
        </inertia>
        <pose>0 0 0 0 0 0</pose>
      </inertial>
      <enable_wind>0</enable_wind>
      <kinematic>0</kinematic>
      <visual name='battery_0_visual'>
        <pose>-0.15 0.17 0 0 1.5708 1.5708</pose>
        <geometry>
          <mesh>
            <scale>1 1 1</scale>
            <uri>model://anna_1/meshes/TattuPlus_battery.stl</uri>
          </mesh>
        </geometry>
        <material>
          <script>
            <name>Gazebo/DarkGrey</name>
            <uri>file://media/materials/scripts/gazebo.material</uri>
          </script>
        </material>
      </visual>
      <collision name='battery_collision'>
        <laser_retro>0</laser_retro>
        <max_contacts>10</max_contacts>
        <pose>0 0 0 0 0 1.5708</pose>
        <geometry>
          <box>
            <size>0.08 0.15 0.217</size>
          </box>
        </geometry>
        <surface>
          <friction>
            <ode>
              <mu>1</mu>
              <mu2>1</mu2>
              <fdir1>0 0 0</fdir1>
              <slip1>0</slip1>
              <slip2>0</slip2>
            </ode>
          </friction>
          <contact>
            <collide_without_contact>0</collide_without_contact>
            <collide_without_contact_bitmask>1</collide_without_contact_bitmask>
            <collide_bitmask>1</collide_bitmask>
            <ode>
              <soft_cfm>0</soft_cfm>
              <soft_erp>0.2</soft_erp>
              <kp>1e+13</kp>
              <kd>1</kd>
              <max_vel>0</max_vel>
              <min_depth>0.001</min_depth>
            </ode>
            <bullet>
              <split_impulse>1</split_impulse>
              <split_impulse_penetration_threshold>-0.01</split_impulse_penetration_threshold>
              <soft_cfm>0</soft_cfm>
              <soft_erp>0.2</soft_erp>
              <kp>1e+13</kp>
              <kd>1</kd>
            </bullet>
          </contact>
        </surface>
      </collision>
    </link>
    <joint name="battery_0_joint" type="fixed">
      <parent>base_link</parent>
      <child>battery_0</child>
      <axis>
        <xyz>0 0 1</xyz>
        <limit>
          <lower>-1e+16</lower>
          <upper>1e+16</upper>
        </limit>
        <dynamics>
      	  <damping>0.004</damping>
        </dynamics>
        <use_parent_model_frame>1</use_parent_model_frame>
      </axis>
      <physics>
        <ode>
          <implicit_spring_damper>1</implicit_spring_damper>
        </ode>
      </physics>
    </joint>
    <link name='battery_1'>
      <pose>-0.06 0.09 -0.08 0 0 1.5608</pose>
      <gravity>1</gravity>
      <self_collide>0</self_collide>
      <velocity_decay/>
      <inertial>
        <mass>4.25</mass>
        <inertia>
          <ixx>0.0272</ixx>
          <ixy>0</ixy>
          <ixz>0</ixz>
          <iyy>0.095625</iyy>
          <iyz>0</iyz>
          <izz>0.212825</izz>
        </inertia>
        <pose>0 0 0 0 0 0</pose>
      </inertial>
      <enable_wind>0</enable_wind>
      <kinematic>0</kinematic>
      <visual name='battery_1_visual'>
        <pose>-0.05 0.06 0 0 1.5708 1.5708</pose>
        <geometry>
          <mesh>
            <scale>1 1 1</scale>
            <uri>model://anna_1/meshes/TattuPlus_battery.stl</uri>
          </mesh>
        </geometry>
        <material>
          <ambient>0.2 0.2 0.2 1.0</ambient>
          <diffuse>0.2 0.2 0.2 1.0</diffuse>
        </material>
      </visual>
      <collision name='battery_collision'>
        <laser_retro>0</laser_retro>
        <max_contacts>10</max_contacts>
        <pose>0 -0.04 0 0 0 0</pose>
        <geometry>
          <box>
            <size>0.08 0.15 0.217</size>
          </box>
        </geometry>
        <surface>
          <friction>
            <ode>
              <mu>1</mu>
              <mu2>1</mu2>
              <fdir1>0 0 0</fdir1>
              <slip1>0</slip1>
              <slip2>0</slip2>
            </ode>
          </friction>
          <contact>
            <collide_without_contact>0</collide_without_contact>
            <collide_without_contact_bitmask>1</collide_without_contact_bitmask>
            <collide_bitmask>1</collide_bitmask>
            <ode>
              <soft_cfm>0</soft_cfm>
              <soft_erp>0.2</soft_erp>
              <kp>1e+13</kp>
              <kd>1</kd>
              <max_vel>0</max_vel>
              <min_depth>0.001</min_depth>
            </ode>
            <bullet>
              <split_impulse>1</split_impulse>
              <split_impulse_penetration_threshold>-0.01</split_impulse_penetration_threshold>
              <soft_cfm>0</soft_cfm>
              <soft_erp>0.2</soft_erp>
              <kp>1e+13</kp>
              <kd>1</kd>
            </bullet>
          </contact>
        </surface>
      </collision>
    </link>
    <joint name="battery_1_joint" type="fixed">
      <parent>base_link</parent>
      <child>battery_1</child>
      <axis>
        <xyz>0 0 1</xyz>
        <limit>
          <lower>-1e+16</lower>
          <upper>1e+16</upper>
        </limit>
        <dynamics>
      	  <damping>0.004</damping>
        </dynamics>
        <use_parent_model_frame>1</use_parent_model_frame>
      </axis>
      <physics>
        <ode>
          <implicit_spring_damper>1</implicit_spring_damper>
        </ode>
      </physics>
    </joint> -->
    <link name="rotor_0">
      <pose>0.49 -0.52 0.05 0.08 -0.08 0</pose>
      <gravity>1</gravity>
      <self_collide>0</self_collide>
      <velocity_decay/>
      <inertial>
        <mass>0.0160769</mass>
        <inertia>
          <ixx>3.8e-07</ixx>
          <ixy>0</ixy>
          <ixz>0</ixz>
          <iyy>2.612e-05</iyy>
          <iyz>0</iyz>
          <izz>2.65e-05</izz>
        </inertia>
        <pose>0 0 0 0 0 0</pose>
      </inertial>
      <enable_wind>0</enable_wind>
      <kinematic>0</kinematic>
      <!-- <visual name='motor_base'>
        <pose>0 -0.001 -0.038 3.14159 0 2.69159</pose>
        <geometry>
          <mesh>
            <scale>1 1 1</scale>
            <uri>model://anna_1/meshes/5010Base.dae</uri>
          </mesh>
        </geometry>
        <material>
          <ambient>0.2 0.2 0.2 1.0</ambient>
          <diffuse>0.2 0.2 0.2 1.0</diffuse>
        </material>
        <transparency>0</transparency>
        <cast_shadows>1</cast_shadows>
      </visual>
      <visual name='rotor_visual'>
        <pose>-0.0303 -0.0476 -0.02 -1.5708 0 0</pose>
        <geometry>
          <mesh>
            <scale>0.0006 0.0006 0.0006</scale>
            <uri>model://anna_1/meshes/R3090_ccw.stl</uri>
          </mesh>
        </geometry>
        <material>
          <ambient>0.2 0.2 0.2 1.0</ambient>
          <diffuse>0.2 0.2 0.2 1.0</diffuse>
        </material>
        </material>
        <transparency>0</transparency>
        <cast_shadows>1</cast_shadows>
      </visual>
      <visual name='rotor_visual_motor_bell'>
        <pose>0 0 -0.032 3.14159 0 0</pose>
        <geometry>
          <mesh>
            <scale>1 1 1</scale>
            <uri>model://anna_1/meshes/5010Bell.dae</uri>
          </mesh>
        </geometry>
        <material>
          <ambient>0.2 0.2 0.2 1.0</ambient>
          <diffuse>0.2 0.2 0.2 1.0</diffuse>
        </material>
        <transparency>0</transparency>
        <cast_shadows>1</cast_shadows>
      </visual> -->
      <visual name='rotor_visual'>
        <pose>0 0 0 0 0 0</pose>
        <geometry>
          <box>
            <size>0.44 0.016923 0.000846</size>
          </box>
        </geometry>
        <material>
          <ambient>0 0 1 1.0</ambient>
          <diffuse>0 0 1 1.0</diffuse>
        </material>
      </visual>
      <collision name='rotor_collision'>
        <laser_retro>0</laser_retro>
        <max_contacts>10</max_contacts>
        <pose>0 0 0 0 0 0</pose>
        <geometry>
          <box>
            <size>0.44 0.016923 0.000846</size>
          </box>
        </geometry>
        <surface>
          <friction>
            <ode>
              <mu>1</mu>
              <mu2>1</mu2>
              <fdir1>0 0 0</fdir1>
              <slip1>0</slip1>
              <slip2>0</slip2>
            </ode>
            <torsional>
              <coefficient>1</coefficient>
              <patch_radius>0</patch_radius>
              <surface_radius>0</surface_radius>
              <use_patch_radius>1</use_patch_radius>
              <ode>
                <slip>0</slip>
              </ode>
            </torsional>
          </friction>
          <bounce>
            <restitution_coefficient>0</restitution_coefficient>
            <threshold>1e+06</threshold>
          </bounce>
          <contact>
            <collide_without_contact>0</collide_without_contact>
            <collide_without_contact_bitmask>1</collide_without_contact_bitmask>
            <collide_bitmask>1</collide_bitmask>
            <ode>
              <soft_cfm>0</soft_cfm>
              <soft_erp>0.2</soft_erp>
              <kp>1e+13</kp>
              <kd>1</kd>
              <max_vel>0</max_vel>
              <min_depth>0.001</min_depth>
            </ode>
            <bullet>
              <split_impulse>1</split_impulse>
              <split_impulse_penetration_threshold>-0.01</split_impulse_penetration_threshold>
              <soft_cfm>0</soft_cfm>
              <soft_erp>0.2</soft_erp>
              <kp>1e+13</kp>
              <kd>1</kd>
            </bullet>
          </contact>
        </surface>
      </collision>
    </link>
    <joint name="rotor_0_joint" type="revolute">
      <parent>base_link</parent>
      <child>rotor_0</child>
      <axis>
        <xyz>0 0 1</xyz>
        <limit>
          <lower>-1e+16</lower>
          <upper>1e+16</upper>
        </limit>
        <dynamics>
          <damping>0.004</damping>
        </dynamics>
        <use_parent_model_frame>1</use_parent_model_frame>
      </axis>
      <physics>
        <ode>
          <implicit_spring_damper>1</implicit_spring_damper>
        </ode>
      </physics>
    </joint>

    <link name="rotor_1">
      <pose>-0.52 0.499 0.05 0.08 -0.08 0</pose>
      <gravity>1</gravity>
      <self_collide>0</self_collide>
      <velocity_decay/>
      <inertial>
        <mass>0.0160769</mass>
        <inertia>
          <ixx>3.8e-07</ixx>
          <ixy>0</ixy>
          <ixz>0</ixz>
          <iyy>2.612e-05</iyy>
          <iyz>0</iyz>
          <izz>2.65e-05</izz>
        </inertia>
        <pose>0 0 0 0 0 0</pose>
      </inertial>
      <enable_wind>0</enable_wind>
      <kinematic>0</kinematic>
      <!-- <visual name='motor_base'>
        <pose>0 -0.001 -0.038 3.14159 0 2.69159</pose>
        <geometry>
          <mesh>
            <scale>1 1 1</scale>
            <uri>model://anna_1/meshes/5010Base.dae</uri>
          </mesh>
        </geometry>
        <material>
          <ambient>0.2 0.2 0.2 1.0</ambient>
          <diffuse>0.2 0.2 0.2 1.0</diffuse>
        </material>
        <transparency>0</transparency>
        <cast_shadows>1</cast_shadows>
      </visual>
      <visual name='rotor_visual'>
        <pose>-0.0303 -0.0476 -0.02 -1.5708 0 0</pose>
        <geometry>
          <mesh>
            <scale>0.0006 0.0006 0.0006</scale>
            <uri>model://anna_1/meshes/R3090_ccw.stl</uri>
          </mesh>
        </geometry>
        <material>
          <ambient>0.2 0.2 0.2 1.0</ambient>
          <diffuse>0.2 0.2 0.2 1.0</diffuse>
        </material>
        <transparency>0</transparency>
        <cast_shadows>1</cast_shadows>
      </visual>
      <visual name='rotor_visual_motor_bell'>
        <pose>0 0 -0.032 3.14159 0 0</pose>
        <geometry>
          <mesh>
            <scale>1 1 1</scale>
            <uri>model://anna_1/meshes/5010Bell.dae</uri>
          </mesh>
        </geometry>
        <material>
          <ambient>0.2 0.2 0.2 1.0</ambient>
          <diffuse>0.2 0.2 0.2 1.0</diffuse>
        </material>
      </visual>   -->
      <visual name='rotor_visual'>
        <pose>0 0 0 0 0 0</pose>
        <geometry>
          <box>
            <size>0.44 0.016923 0.000846</size>
          </box>
        </geometry>
        <material>
          <ambient>0 0 1 1.0</ambient>
          <diffuse>0 0 1 1.0</diffuse>
        </material>
      </visual>
      <collision name='rotor_collision'>
        <laser_retro>0</laser_retro>
        <max_contacts>10</max_contacts>
        <pose>0 0 0 0 0 0</pose>
        <geometry>
          <box>
            <size>0.44 0.016923 0.000846</size>
          </box>
        </geometry>
        <surface>
          <friction>
            <ode>
              <mu>1</mu>
              <mu2>1</mu2>
              <fdir1>0 0 0</fdir1>
              <slip1>0</slip1>
              <slip2>0</slip2>
            </ode>
            <torsional>
              <coefficient>1</coefficient>
              <patch_radius>0</patch_radius>
              <surface_radius>0</surface_radius>
              <use_patch_radius>1</use_patch_radius>
              <ode>
                <slip>0</slip>
              </ode>
            </torsional>
          </friction>
          <bounce>
            <restitution_coefficient>0</restitution_coefficient>
            <threshold>1e+06</threshold>
          </bounce>
          <contact>
            <collide_without_contact>0</collide_without_contact>
            <collide_without_contact_bitmask>1</collide_without_contact_bitmask>
            <collide_bitmask>1</collide_bitmask>
            <ode>
              <soft_cfm>0</soft_cfm>
              <soft_erp>0.2</soft_erp>
              <kp>1e+13</kp>
              <kd>1</kd>
              <max_vel>0</max_vel>
              <min_depth>0.001</min_depth>
            </ode>
            <bullet>
              <split_impulse>1</split_impulse>
              <split_impulse_penetration_threshold>-0.01</split_impulse_penetration_threshold>
              <soft_cfm>0</soft_cfm>
              <soft_erp>0.2</soft_erp>
              <kp>1e+13</kp>
              <kd>1</kd>
            </bullet>
          </contact>
        </surface>
      </collision>
    </link>
    <joint name="rotor_1_joint" type="revolute">
      <parent>base_link</parent>
      <child>rotor_1</child>
      <axis>
        <xyz>0 0 1</xyz>
        <limit>
          <lower>-1e+16</lower>
          <upper>1e+16</upper>
        </limit>
        <dynamics>
          <damping>0.004</damping>
        </dynamics>
        <use_parent_model_frame>1</use_parent_model_frame>
      </axis>
      <physics>
        <ode>
          <implicit_spring_damper>1</implicit_spring_damper>
        </ode>
      </physics>
    </joint>

    <link name="rotor_2">
      <pose>0.5085 0.5 0.05 0.08 0.08 0</pose>
      <gravity>1</gravity>
      <self_collide>0</self_collide>
      <velocity_decay/>
      <inertial>
        <mass>0.0160769</mass>
        <inertia>
          <ixx>3.8e-07</ixx>
          <ixy>0</ixy>
          <ixz>0</ixz>
          <iyy>2.612e-05</iyy>
          <iyz>0</iyz>
          <izz>2.65e-05</izz>
        </inertia>
        <pose>0 0 0 0 0 0</pose>
      </inertial>
      <enable_wind>0</enable_wind>
      <kinematic>0</kinematic>
      <!-- <visual name='motor_base'>
        <pose>0 -0.001 -0.038 3.14159 0 2.69159</pose>
        <geometry>
          <mesh>
            <scale>1 1 1</scale>
            <uri>model://anna_1/meshes/5010Base.dae</uri>
          </mesh>
        </geometry>
        <material>
          <ambient>0.2 0.2 0.2 1.0</ambient>
          <diffuse>0.2 0.2 0.2 1.0</diffuse>
        </material>
        <transparency>0</transparency>
        <cast_shadows>1</cast_shadows>
      </visual>
      <visual name='rotor_visual'>
        <pose>-0.0303 -0.0476 -0.02 -1.5708 0 0</pose>
        <geometry>
          <mesh>
            <scale>0.0006 0.0006 0.0006</scale>
            <uri>model://anna_1/meshes/R3090_cw.stl</uri>
          </mesh>
        </geometry>
        <material>
          <ambient>0.2 0.2 0.2 1.0</ambient>
          <diffuse>0.2 0.2 0.2 1.0</diffuse>
        </material>
        <transparency>0</transparency>
        <cast_shadows>1</cast_shadows>
      </visual>
      <visual name='rotor_visual_motor_bell'>
        <pose>0 0 -0.032 3.14159 0 0</pose>
        <geometry>
          <mesh>
            <scale>1 1 1</scale>
            <uri>model://anna_1/meshes/5010Bell.dae</uri>
          </mesh>
        </geometry>
        <material>
          <ambient>0.2 0.2 0.2 1.0</ambient>
          <diffuse>0.2 0.2 0.2 1.0</diffuse>
        </material>
        <transparency>0</transparency>
        <cast_shadows>1</cast_shadows>
      </visual> -->
      <visual name='rotor_visual'>
        <pose>0 0 0 0 0 0</pose>
        <geometry>
          <box>
            <size>0.44 0.016923 0.000846</size>
          </box>
        </geometry>
        <material>
          <ambient>0 1 0 1.0</ambient>
          <diffuse>0 1 0 1.0</diffuse>
        </material>
      </visual>
      <collision name='rotor_collision'>
        <laser_retro>0</laser_retro>
        <max_contacts>10</max_contacts>
        <pose>0 0 0 0 0 0</pose>
        <geometry>
          <box>
            <size>0.44 0.016923 0.000846</size>
          </box>
        </geometry>
        <surface>
          <friction>
            <ode>
              <mu>1</mu>
              <mu2>1</mu2>
              <fdir1>0 0 0</fdir1>
              <slip1>0</slip1>
              <slip2>0</slip2>
            </ode>
            <torsional>
              <coefficient>1</coefficient>
              <patch_radius>0</patch_radius>
              <surface_radius>0</surface_radius>
              <use_patch_radius>1</use_patch_radius>
              <ode>
                <slip>0</slip>
              </ode>
            </torsional>
          </friction>
          <bounce>
            <restitution_coefficient>0</restitution_coefficient>
            <threshold>1e+06</threshold>
          </bounce>
          <contact>
            <collide_without_contact>0</collide_without_contact>
            <collide_without_contact_bitmask>1</collide_without_contact_bitmask>
            <collide_bitmask>1</collide_bitmask>
            <ode>
              <soft_cfm>0</soft_cfm>
              <soft_erp>0.2</soft_erp>
              <kp>1e+13</kp>
              <kd>1</kd>
              <max_vel>0</max_vel>
              <min_depth>0.001</min_depth>
            </ode>
            <bullet>
              <split_impulse>1</split_impulse>
              <split_impulse_penetration_threshold>-0.01</split_impulse_penetration_threshold>
              <soft_cfm>0</soft_cfm>
              <soft_erp>0.2</soft_erp>
              <kp>1e+13</kp>
              <kd>1</kd>
            </bullet>
          </contact>
        </surface>
      </collision>
    </link>
    <joint name="rotor_2_joint" type="revolute">
      <parent>base_link</parent>
      <child>rotor_2</child>
      <axis>
        <xyz>0 0 1</xyz>
        <limit>
          <lower>-1e+16</lower>
          <upper>1e+16</upper>
        </limit>
        <dynamics>
          <damping>0.004</damping>
        </dynamics>
        <use_parent_model_frame>1</use_parent_model_frame>
      </axis>
      <physics>
        <ode>
          <implicit_spring_damper>1</implicit_spring_damper>
        </ode>
      </physics>
    </joint>

    <link name="rotor_3">
      <pose>-0.5085 -0.52 0.05 0.08 0.08 0</pose>
      <gravity>1</gravity>
      <self_collide>0</self_collide>
      <velocity_decay/>
      <inertial>
        <mass>0.0160769</mass>
        <inertia>
          <ixx>3.8e-07</ixx>
          <ixy>0</ixy>
          <ixz>0</ixz>
          <iyy>2.612e-05</iyy>
          <iyz>0</iyz>
          <izz>2.65e-05</izz>
        </inertia>
        <pose>0 0 0 0 0 0</pose>
      </inertial>
      <enable_wind>0</enable_wind>
      <kinematic>0</kinematic>
      <!-- <visual name='motor_base'>
        <pose>0 -0.001 -0.038 3.14159 0 2.69159</pose>
        <geometry>
          <mesh>
            <scale>1 1 1</scale>
            <uri>model://anna_1/meshes/5010Base.dae</uri>
          </mesh>
        </geometry>
        <material>
          <ambient>0.2 0.2 0.2 1.0</ambient>
          <diffuse>0.2 0.2 0.2 1.0</diffuse>
        </material>
        <transparency>0</transparency>
        <cast_shadows>1</cast_shadows>
      </visual>
      <visual name='rotor_visual'>
        <pose>-0.0303 -0.0476 -0.02 -1.5708 0 0</pose>
        <geometry>
          <mesh>
            <scale>0.0006 0.0006 0.0006</scale>
            <uri>model://anna_1/meshes/R3090_cw.stl</uri>
          </mesh>
        </geometry>
        <material>
          <ambient>0.2 0.2 0.2 1.0</ambient>
          <diffuse>0.2 0.2 0.2 1.0</diffuse>
        </material>
        <transparency>0</transparency>
        <cast_shadows>1</cast_shadows>
      </visual>
      <visual name='rotor_visual_motor_bell'>
        <pose>0 0 -0.032 3.14159 0 0</pose>
        <geometry>
          <mesh>
            <scale>1 1 1</scale>
            <uri>model://anna_1/meshes/5010Bell.dae</uri>
          </mesh>
        </geometry>
        <material>
          <ambient>0.2 0.2 0.2 1.0</ambient>
          <diffuse>0.2 0.2 0.2 1.0</diffuse>
        </material>
        <transparency>0</transparency>
        <cast_shadows>1</cast_shadows>
      </visual> -->
      <visual name='rotor_visual'>
        <pose>0 0 0 0 0 0</pose>
        <geometry>
          <box>
            <size>0.44 0.016923 0.000846</size>
          </box>
        </geometry>
        <material>
          <ambient>0 1 0 1.0</ambient>
          <diffuse>0 1 0 1.0</diffuse>
        </material>
      </visual>
      <collision name='rotor_collision'>
        <laser_retro>0</laser_retro>
        <max_contacts>10</max_contacts>
        <pose>0 0 0 0 0 0</pose>
        <geometry>
          <box>
            <size>0.44 0.016923 0.000846</size>
          </box>
        </geometry>
        <surface>
          <friction>
            <ode>
              <mu>1</mu>
              <mu2>1</mu2>
              <fdir1>0 0 0</fdir1>
              <slip1>0</slip1>
              <slip2>0</slip2>
            </ode>
            <torsional>
              <coefficient>1</coefficient>
              <patch_radius>0</patch_radius>
              <surface_radius>0</surface_radius>
              <use_patch_radius>1</use_patch_radius>
              <ode>
                <slip>0</slip>
              </ode>
            </torsional>
          </friction>
          <bounce>
            <restitution_coefficient>0</restitution_coefficient>
            <threshold>1e+06</threshold>
          </bounce>
          <contact>
            <collide_without_contact>0</collide_without_contact>
            <collide_without_contact_bitmask>1</collide_without_contact_bitmask>
            <collide_bitmask>1</collide_bitmask>
            <ode>
              <soft_cfm>0</soft_cfm>
              <soft_erp>0.2</soft_erp>
              <kp>1e+13</kp>
              <kd>1</kd>
              <max_vel>0</max_vel>
              <min_depth>0.001</min_depth>
            </ode>
            <bullet>
              <split_impulse>1</split_impulse>
              <split_impulse_penetration_threshold>-0.01</split_impulse_penetration_threshold>
              <soft_cfm>0</soft_cfm>
              <soft_erp>0.2</soft_erp>
              <kp>1e+13</kp>
              <kd>1</kd>
            </bullet>
          </contact>
        </surface>
      </collision>
    </link>
    <joint name="rotor_3_joint" type="revolute">
      <parent>base_link</parent>
      <child>rotor_3</child>
      <axis>
        <xyz>0 0 1</xyz>
        <limit>
          <lower>-1e+16</lower>
          <upper>1e+16</upper>
        </limit>
        <dynamics>
          <damping>0.004</damping>
        </dynamics>
        <use_parent_model_frame>1</use_parent_model_frame>
      </axis>
      <physics>
        <ode>
          <implicit_spring_damper>1</implicit_spring_damper>
        </ode>
      </physics>
    </joint>

    <!--
    <include>
      <uri>model://gimbal_small_2d</uri>
      <pose>0.025 -0.01 -0.13 1.57 0 1.57</pose>
    </include>

    <joint name="iris_gimbal_mount" type="revolute">
      <parent>base_link</parent>
      <child>gimbal_small_2d::base_link</child>
      <axis>
        <limit>
          <lower>0</lower>
          <upper>0</upper>
        </limit>
        <xyz>0 0 1</xyz>
        <use_parent_model_frame>1</use_parent_model_frame>
      </axis>
    </joint>
    -->
    <!-- rotor_0_blade_1 -->
    <plugin name="rotor_0_blade_1" filename="gz::sim::systems::LiftDrag">
      <a0>0.3</a0>
      <alpha_stall>1.4</alpha_stall>
      <cla>4.2500</cla>
      <cda>0.10</cda>
      <cma>0.00</cma>
      <cla_stall>-0.025</cla_stall>
      <cda_stall>0.0</cda_stall>
      <cma_stall>0.0</cma_stall>
      <area>0.008</area>
      <air_density>1.2041</air_density>
      <cp>0.2 0 0</cp>
      <forward>0 1 0</forward>
      <upward>0 0 1</upward>
      <link_name>rotor_0</link_name>
    </plugin>
    <!-- rotor_0_blade_2 -->
    <plugin name="rotor_0_blade_2" filename="gz::sim::systems::LiftDrag">
      <a0>0.3</a0>
      <alpha_stall>1.4</alpha_stall>
      <cla>4.2500</cla>
      <cda>0.10</cda>
      <cma>0.00</cma>
      <cla_stall>-0.025</cla_stall>
      <cda_stall>0.0</cda_stall>
      <cma_stall>0.0</cma_stall>
      <area>0.008</area>
      <air_density>1.2041</air_density>
      <cp>-0.2 0 0</cp>
      <forward>0 -1 0</forward>
      <upward>0 0 1</upward>
      <link_name>rotor_0</link_name>
    </plugin>

    <!-- rotor_1_blade_1 -->
    <plugin filename="gz-sim-lift-drag-system"
        name="gz::sim::systems::LiftDrag">
      <a0>0.3</a0>
      <alpha_stall>1.4</alpha_stall>
      <cla>4.2500</cla>
      <cda>0.10</cda>
      <cma>0.00</cma>
      <cla_stall>-0.025</cla_stall>
      <cda_stall>0.0</cda_stall>
      <cma_stall>0.0</cma_stall>
      <area>0.008</area>
      <air_density>1.2041</air_density>
      <cp>0.2 0 0</cp>
      <forward>0 1 0</forward>
      <upward>0 0 1</upward>
      <link_name>rotor_1</link_name>
    </plugin>
    <!-- rotor_1_blade_2 -->
    <plugin filename="gz-sim-lift-drag-system"
        name="gz::sim::systems::LiftDrag">
      <a0>0.3</a0>
      <alpha_stall>1.4</alpha_stall>
      <cla>4.2500</cla>
      <cda>0.10</cda>
      <cma>0.00</cma>
      <cla_stall>-0.025</cla_stall>
      <cda_stall>0.0</cda_stall>
      <cma_stall>0.0</cma_stall>
      <area>0.008</area>
      <air_density>1.2041</air_density>
      <cp>-0.2 0 0</cp>
      <forward>0 -1 0</forward>
      <upward>0 0 1</upward>
      <link_name>rotor_1</link_name>
    </plugin>

    <!-- rotor_2_blade_1 -->
    <plugin filename="gz-sim-lift-drag-system"
        name="gz::sim::systems::LiftDrag">
      <a0>0.3</a0>
      <alpha_stall>1.4</alpha_stall>
      <cla>4.2500</cla>
      <cda>0.10</cda>
      <cma>0.00</cma>
      <cla_stall>-0.025</cla_stall>
      <cda_stall>0.0</cda_stall>
      <cma_stall>0.0</cma_stall>
      <area>0.008</area>
      <air_density>1.2041</air_density>
      <cp>0.2 0 0</cp>
      <forward>0 -1 0</forward>
      <upward>0 0 1</upward>
      <link_name>rotor_2</link_name>
    </plugin>
    <!-- rotor_2_blade_2 -->
    <plugin filename="gz-sim-lift-drag-system"
        name="gz::sim::systems::LiftDrag">
      <a0>0.3</a0>
      <alpha_stall>1.4</alpha_stall>
      <cla>4.2500</cla>
      <cda>0.10</cda>
      <cma>0.00</cma>
      <cla_stall>-0.025</cla_stall>
      <cda_stall>0.0</cda_stall>
      <cma_stall>0.0</cma_stall>
      <area>0.008</area>
      <air_density>1.2041</air_density>
      <cp>-0.2 0 0</cp>
      <forward>0 1 0</forward>
      <upward>0 0 1</upward>
      <link_name>rotor_2</link_name>
    </plugin>

    <!-- rotor_3_blade_1 -->
    <plugin filename="gz-sim-lift-drag-system"
        name="gz::sim::systems::LiftDrag">
      <a0>0.3</a0>
      <alpha_stall>1.4</alpha_stall>
      <cla>4.2500</cla>
      <cda>0.10</cda>
      <cma>0.00</cma>
      <cla_stall>-0.025</cla_stall>
      <cda_stall>0.0</cda_stall>
      <cma_stall>0.0</cma_stall>
      <area>0.008</area>
      <air_density>1.2041</air_density>
      <cp>0.2 0 0</cp>
      <forward>0 -1 0</forward>
      <upward>0 0 1</upward>
      <link_name>rotor_3</link_name>
    </plugin>
    <!-- rotor_3_blade_2 -->
    <plugin filename="gz-sim-lift-drag-system"
        name="gz::sim::systems::LiftDrag">
      <a0>0.3</a0>
      <alpha_stall>1.4</alpha_stall>
      <cla>4.2500</cla>
      <cda>0.10</cda>
      <cma>0.00</cma>
      <cla_stall>-0.025</cla_stall>
      <cda_stall>0.0</cda_stall>
      <cma_stall>0.0</cma_stall>
      <area>0.008</area>
      <air_density>1.2041</air_density>
      <cp>-0.2 0 0</cp>
      <forward>0 1 0</forward>
      <upward>0 0 1</upward>
      <link_name>rotor_3</link_name>
    </plugin>

    <plugin name="ArduPilotPlugin" filename="ArduPilotPlugin">
      <!-- Port settings -->
      <fdm_addr>127.0.0.1</fdm_addr>
      <fdm_port_in>9002</fdm_port_in>
      <connectionTimeoutMaxCount>5</connectionTimeoutMaxCount>
      <lock_step>1</lock_step>
      <have_32_channels>0</have_32_channels>

      <!-- Frame conventions -->
      <modelXYZToAirplaneXForwardZDown degrees="true">0 0 0 180 0 0</modelXYZToAirplaneXForwardZDown>
      <gazeboXYZToNED degrees="true">0 0 0 180 0 90</gazeboXYZToNED>

      <!-- Sensors -->
      <imuName>base_link::imu_sensor</imuName>

      <!--
          incoming control command [0, 1]
          so offset it by 0 to get [0, 1]
          and divide max target by 1.
          offset = 0
          multiplier = 838 max rpm / 1 = 838
        -->
      <control channel="0">
        <jointName>rotor_0_joint</jointName>
        <useForce>1</useForce>
        <multiplier>832</multiplier>
        <offset>0</offset>
        <servo_min>1100</servo_min>
        <servo_max>1900</servo_max>
        <type>VELOCITY</type>
        <p_gain>0.2</p_gain>
        <i_gain>0</i_gain>
        <d_gain>0</d_gain>
        <i_max>0</i_max>
        <i_min>0</i_min>
        <cmd_max>3</cmd_max>
        <cmd_min>-3</cmd_min>
        <controlVelocitySlowdownSim>1</controlVelocitySlowdownSim>
      </control>

      <control channel="1">
        <jointName>rotor_1_joint</jointName>
        <useForce>1</useForce>
        <multiplier>832</multiplier>
        <offset>0</offset>
        <servo_min>1100</servo_min>
        <servo_max>1900</servo_max>
        <type>VELOCITY</type>
        <p_gain>0.2</p_gain>
        <i_gain>0</i_gain>
        <d_gain>0</d_gain>
        <i_max>0</i_max>
        <i_min>0</i_min>
        <cmd_max>3</cmd_max>
        <cmd_min>-3</cmd_min>
        <controlVelocitySlowdownSim>1</controlVelocitySlowdownSim>
      </control>

      <control channel="2">
        <jointName>rotor_2_joint</jointName>
        <useForce>1</useForce>
        <multiplier>-832</multiplier>
        <offset>0</offset>
        <servo_min>1100</servo_min>
        <servo_max>1900</servo_max>
        <type>VELOCITY</type>
        <p_gain>0.2</p_gain>
        <i_gain>0</i_gain>
        <d_gain>0</d_gain>
        <i_max>0</i_max>
        <i_min>0</i_min>
        <cmd_max>3</cmd_max>
        <cmd_min>-3</cmd_min>
        <controlVelocitySlowdownSim>1</controlVelocitySlowdownSim>
      </control>

      <control channel="3">
        <jointName>rotor_3_joint</jointName>
        <useForce>1</useForce>
        <multiplier>-832</multiplier>
        <offset>0</offset>
        <servo_min>1100</servo_min>
        <servo_max>1900</servo_max>
        <type>VELOCITY</type>
        <p_gain>0.2</p_gain>
        <i_gain>0</i_gain>
        <d_gain>0</d_gain>
        <i_max>0</i_max>
        <i_min>0</i_min>
        <cmd_max>3</cmd_max>
        <cmd_min>-3</cmd_min>
        <controlVelocitySlowdownSim>1</controlVelocitySlowdownSim>
      </control>
    </plugin>
  </model>
</sdf>
